Workbook
Name RECAUDACION___ACUERDOS_DE_PAGO_EN_OFICINAS_COMERCIALES: #REF!
Name TABLE: '[1]Comparación (2)'!$D$15:$U$15
Name TABLE_2: '[1]Comparación (2)'!$D$16:$U$16
Name TABLE_201: '[1]Comparación (2)'!$B$12:$U$19
Name TABLE01: '[1]Comparación (2)'!$B$2:$T$9

Sheet Resumen PE
A1: Cartera
A2: PE Calls | B2: =SUM('Cartera_Viva-Calls'!AJ7:AJ8) -> 33128.766 | C2: =B2/$B$5 -> 0.0058335829
A3: PE Otros | B3: =+SUM('Cartera_Viva-Otros'!AN:AN) -> 4330544.1 | C3: =B3/$B$5 -> 0.76255747
A4: PE Saldos No Util | B4: =+SUM(Saldos_No_Util!O:O) -> 1315301.2 | C4: =B4/$B$5 -> 0.23160894 | D4: Unidades expresión | E4: 1000000
A5: TOTAL PE | B5: =+SUM(B2:B4) -> 5678974
A7: CUADRO A | D7: CUADRO B | G7: CUADRO C | J7: CUADRO D | M7: CUADRO E | S7: CUADRO F
A8: Montos de previsiones (en millones de $) | B8: Monto al | D8: Monto de previsiones (PCE) abiertas por stages (en millones de $) | E8: Monto PCE al | G8: Monto de las exposiciones totales (EAD) abiertas por stages (en millones de $) | H8: Monto exposiciones (EAD) al | J8: Monto de PCE y EAD abiertas por stage y segmento (en millones de $) Carteras/Segmentos (*) | K8: Monto al | M8: Integrar el total de PCE y los parámetros aplicados para cada segmento definido por la entidad (en millones de $) Cartera-Segmento (*)\Concepto | N8: Monto PCE | O8: % PD media (**) | P8: % LGD media (**) | Q8: Monto EAD | S8: Partidas fuera de balance (*) (en millones de $) | T8: Saldo contable PFB | U8: CCF (%) | V8: Monto Exposición (EAD) | W8: Monto
B9: 46112 | E9: =$B$9 -> 46112 | H9: =$B$9 -> 46112 | K9: =$B$9 -> 46112 | W9: PCE
A10: Previsiones totales según NIIF 9 (PCE) | B10: =+B5/$E$4 -> 5.678974 | D10: Stage 1 | E10: =+(SUMIF('Cartera_Viva-Otros'!AL:AL,"1",'Cartera_Viva-Otros'!AN:AN)+SUMIF(Saldos_No_Util!K:K,"1",Saldos_No_Util!O:O)+SUMIF('Cartera_Viva-Calls'!Z:Z,"1",'Cartera_Viva-Calls'!AJ:AJ))/$E$4 -> 3.5256465 | G10: Stage 1 | H10: =+(SUMIF('Cartera_Viva-Otros'!AL:AL,"1",'Cartera_Viva-Otros'!AM:AM)+SUMIF(Saldos_No_Util!K:K,"1",Saldos_No_Util!G:G)+SUMIF('Cartera_Viva-Calls'!Z:Z,"1",'Cartera_Viva-Calls'!AC:AC))/$E$4 -> 1270.3831 | I10: =H10*1000000 -> 1.2703831e+09 | J10: PCE Cartera minorista | K10: =+(SUMIFS('Cartera_Viva-Otros'!AN:AN,'Cartera_Viva-Otros'!P:P,"F")+SUMIFS(Saldos_No_Util!O:O,Saldos_No_Util!P:P,"F"))/$E$4 -> 1.1600159 | M10: Stage 1 | S10: Stage 1
A11: Previsiones regulatorias contabilizadas | D11: Stage 2 | E11: =+(SUMIF('Cartera_Viva-Otros'!AL:AL,"2",'Cartera_Viva-Otros'!AN:AN)+SUMIF(Saldos_No_Util!K:K,"2",Saldos_No_Util!O:O)+SUMIF('Cartera_Viva-Calls'!Z:Z,"2",'Cartera_Viva-Calls'!AJ:AJ))/$E$4 -> 0 | G11: Stage 2 | H11: =+(SUMIF('Cartera_Viva-Otros'!AL:AL,"2",'Cartera_Viva-Otros'!AM:AM)+SUMIF(Saldos_No_Util!K:K,"2",Saldos_No_Util!G:G)+SUMIF('Cartera_Viva-Calls'!Z:Z,"2",'Cartera_Viva-Calls'!AC:AC))/$E$4 -> 0 | I11: =H11*1000000 -> 0 | J11: EAD Cartera minorista | K11: =+(SUMIFS('Cartera_Viva-Otros'!AM:AM,'Cartera_Viva-Otros'!P:P,"f")+SUMIFS(Saldos_No_Util!G:G,Saldos_No_Util!P:P,"F"))/$E$4 -> 152.99962 | M11: Cartera Minorista | N11: =+(SUMIFS('Cartera_Viva-Otros'!AN:AN,'Cartera_Viva-Otros'!AL:AL,"1",'Cartera_Viva-Otros'!P:P,"F")+SUMIFS(Saldos_No_Util!O:O,Saldos_No_Util!K:K,"1",Saldos_No_Util!P:P,"F"))/$E$4 -> 0.80985861 | O11: =AVERAGEIFS('Cartera_Viva-Otros'!AJ:AJ,'Cartera_Viva-Otros'!AL:AL,"1",'Cartera_Viva-Otros'!P:P,"F") -> #DIV/0! | P11: =AVERAGEIFS('Cartera_Viva-Otros'!AK:AK,'Cartera_Viva-Otros'!AL:AL,"1",'Cartera_Viva-Otros'!P:P,"F") -> #DIV/0! | Q11: =+(SUMIFS('Cartera_Viva-Otros'!AM:AM,'Cartera_Viva-Otros'!AL:AL,"1",'Cartera_Viva-Otros'!P:P,"F")+SUMIFS(Saldos_No_Util!G:G,Saldos_No_Util!K:K,"1",Saldos_No_Util!P:P,"F"))/$E$4 -> 152.28764 | S11: Saldo no utilizado TC | T11: =+SUMIFS(Saldos_No_Util!G:G,Saldos_No_Util!K:K,"1",Saldos_No_Util!Q:Q,'Resumen PE'!S11)/$E$4 -> 168.32987 | U11: =+AVERAGEIFS(Saldos_No_Util!N:N,Saldos_No_Util!K:K,"1",Saldos_No_Util!Q:Q,'Resumen PE'!S11) -> 0.4 | V11: =+T11*U11 -> 67.331949 | W11: =SUMIFS(Saldos_No_Util!O:O,Saldos_No_Util!K:K,"1",Saldos_No_Util!Q:Q,'Resumen PE'!S11)/$E$4 -> 0.89517043
D12: Stage 3 | E12: =+(SUMIF('Cartera_Viva-Otros'!AL:AL,"3",'Cartera_Viva-Otros'!AN:AN)+SUMIF(Saldos_No_Util!K:K,"3",Saldos_No_Util!O:O)+SUMIF('Cartera_Viva-Calls'!Z:Z,"3",'Cartera_Viva-Calls'!AJ:AJ))/$E$4 -> 2.1533275 | G12: Stage 3 | H12: =+(SUMIF('Cartera_Viva-Otros'!AL:AL,"3",'Cartera_Viva-Otros'!AM:AM)+SUMIF(Saldos_No_Util!K:K,"3",Saldos_No_Util!G:G)+SUMIF('Cartera_Viva-Calls'!Z:Z,"3",'Cartera_Viva-Calls'!AC:AC))/$E$4 -> 2.5151449 | I12: =H12*1000000 -> 2515144.9 | J12: Tarjetas_de_Crédito | K12: =+SUMIFS('Cartera_Viva-Otros'!AM:AM,'Cartera_Viva-Otros'!AO:AO,'Resumen PE'!J12,'Cartera_Viva-Otros'!P:P,"F")/$E$4 -> 0 | M12: Tarjetas_de_Crédito | N12: =+SUMIFS('Cartera_Viva-Otros'!AN:AN,'Cartera_Viva-Otros'!AL:AL,"1",'Cartera_Viva-Otros'!P:P,"F",'Cartera_Viva-Otros'!AO:AO,'Resumen PE'!M12)/$E$4 -> 0 | O12: =IFERROR(AVERAGEIFS('Cartera_Viva-Otros'!AJ:AJ,'Cartera_Viva-Otros'!AL:AL,"1",'Cartera_Viva-Otros'!P:P,"F",'Cartera_Viva-Otros'!AO:AO,'Resumen PE'!M12),"-") -> - | P12: =IFERROR(AVERAGEIFS('Cartera_Viva-Otros'!AK:AK,'Cartera_Viva-Otros'!AL:AL,"1",'Cartera_Viva-Otros'!P:P,"F",'Cartera_Viva-Otros'!AO:AO,'Resumen PE'!M12),"-") -> - | Q12: =+SUMIFS('Cartera_Viva-Otros'!AM:AM,'Cartera_Viva-Otros'!AL:AL,"1",'Cartera_Viva-Otros'!P:P,"F",'Cartera_Viva-Otros'!AO:AO,'Resumen PE'!M12)/$E$4 -> 0 | S12: Saldo no utilizado ACC | T12: =+SUMIFS(Saldos_No_Util!G:G,Saldos_No_Util!K:K,"1",Saldos_No_Util!Q:Q,'Resumen PE'!S12)/$E$4 -> 11.526606 | U12: =+AVERAGEIFS(Saldos_No_Util!N:N,Saldos_No_Util!K:K,"1",Saldos_No_Util!Q:Q,'Resumen PE'!S12) -> 0.73333333 | V12: =+T12*U12 -> 8.4528444 | W12: =+SUMIFS(Saldos_No_Util!O:O,Saldos_No_Util!K:K,"1",Saldos_No_Util!Q:Q,'Resumen PE'!S12)/$E$4 -> 0.069973463
J13: Prestamos Personales | K13: =+SUMIFS('Cartera_Viva-Otros'!AM:AM,'Cartera_Viva-Otros'!AO:AO,'Resumen PE'!J13,'Cartera_Viva-Otros'!P:P,"F")/$E$4 -> 0 | M13: Prestamos Personales | N13: =+SUMIFS('Cartera_Viva-Otros'!AN:AN,'Cartera_Viva-Otros'!AL:AL,"1",'Cartera_Viva-Otros'!P:P,"F",'Cartera_Viva-Otros'!AO:AO,'Resumen PE'!M13)/$E$4 -> 0 | O13: =IFERROR(AVERAGEIFS('Cartera_Viva-Otros'!AJ:AJ,'Cartera_Viva-Otros'!AL:AL,"1",'Cartera_Viva-Otros'!P:P,"F",'Cartera_Viva-Otros'!AO:AO,'Resumen PE'!M13),"-") -> - | P13: =IFERROR(AVERAGEIFS('Cartera_Viva-Otros'!AK:AK,'Cartera_Viva-Otros'!AL:AL,"1",'Cartera_Viva-Otros'!P:P,"F",'Cartera_Viva-Otros'!AO:AO,'Resumen PE'!M13),"-") -> - | Q13: =+SUMIFS('Cartera_Viva-Otros'!AM:AM,'Cartera_Viva-Otros'!AL:AL,"1",'Cartera_Viva-Otros'!P:P,"F",'Cartera_Viva-Otros'!AO:AO,'Resumen PE'!M13)/$E$4 -> 0 | S13: Stage 2
J14: Prestamos a Sola Firma | K14: =+SUMIFS('Cartera_Viva-Otros'!AM:AM,'Cartera_Viva-Otros'!AO:AO,'Resumen PE'!J14,'Cartera_Viva-Otros'!P:P,"F")/$E$4 -> 0 | M14: Prestamos a Sola Firma | N14: =+SUMIFS('Cartera_Viva-Otros'!AN:AN,'Cartera_Viva-Otros'!AL:AL,"1",'Cartera_Viva-Otros'!P:P,"F",'Cartera_Viva-Otros'!AO:AO,'Resumen PE'!M14)/$E$4 -> 0 | O14: =IFERROR(AVERAGEIFS('Cartera_Viva-Otros'!AJ:AJ,'Cartera_Viva-Otros'!AL:AL,"1",'Cartera_Viva-Otros'!P:P,"F",'Cartera_Viva-Otros'!AO:AO,'Resumen PE'!M14),"-") -> - | P14: =IFERROR(AVERAGEIFS('Cartera_Viva-Otros'!AK:AK,'Cartera_Viva-Otros'!AL:AL,"1",'Cartera_Viva-Otros'!P:P,"F",'Cartera_Viva-Otros'!AO:AO,'Resumen PE'!M14),"-") -> - | Q14: =+SUMIFS('Cartera_Viva-Otros'!AM:AM,'Cartera_Viva-Otros'!AL:AL,"1",'Cartera_Viva-Otros'!P:P,"F",'Cartera_Viva-Otros'!AO:AO,'Resumen PE'!M14)/$E$4 -> 0 | S14: Saldo no utilizado TC | T14: =+SUMIFS(Saldos_No_Util!G:G,Saldos_No_Util!K:K,"2",Saldos_No_Util!Q:Q,'Resumen PE'!S14)/$E$4 -> 0 | U14: =+IFERROR(AVERAGEIFS(Saldos_No_Util!N:N,Saldos_No_Util!K:K,"2",Saldos_No_Util!Q:Q,'Resumen PE'!S14),"-") -> - | V14: =+IFERROR(T14*U14,"-") -> - | W14: =+IFERROR(SUMIFS(Saldos_No_Util!O:O,Saldos_No_Util!K:K,"2",Saldos_No_Util!Q:Q,'Resumen PE'!S14)/$E$4,"-") -> 0
J15: ACC | K15: =+SUMIFS('Cartera_Viva-Otros'!AM:AM,'Cartera_Viva-Otros'!AO:AO,'Resumen PE'!J15,'Cartera_Viva-Otros'!P:P,"F")/$E$4 -> 0 | M15: ACC | N15: =+SUMIFS('Cartera_Viva-Otros'!AN:AN,'Cartera_Viva-Otros'!AL:AL,"1",'Cartera_Viva-Otros'!P:P,"F",'Cartera_Viva-Otros'!AO:AO,'Resumen PE'!M15)/$E$4 -> 0 | O15: =IFERROR(AVERAGEIFS('Cartera_Viva-Otros'!AJ:AJ,'Cartera_Viva-Otros'!AL:AL,"1",'Cartera_Viva-Otros'!P:P,"F",'Cartera_Viva-Otros'!AO:AO,'Resumen PE'!M15),"-") -> - | P15: =IFERROR(AVERAGEIFS('Cartera_Viva-Otros'!AK:AK,'Cartera_Viva-Otros'!AL:AL,"1",'Cartera_Viva-Otros'!P:P,"F",'Cartera_Viva-Otros'!AO:AO,'Resumen PE'!M15),"-") -> - | Q15: =+SUMIFS('Cartera_Viva-Otros'!AM:AM,'Cartera_Viva-Otros'!AL:AL,"1",'Cartera_Viva-Otros'!P:P,"F",'Cartera_Viva-Otros'!AO:AO,'Resumen PE'!M15)/$E$4 -> 0 | S15: Saldo no utilizado ACC | T15: =+SUMIFS(Saldos_No_Util!G:G,Saldos_No_Util!K:K,"2",Saldos_No_Util!Q:Q,'Resumen PE'!S15)/$E$4 -> 0 | U15: =+IFERROR(AVERAGEIFS(Saldos_No_Util!N:N,Saldos_No_Util!K:K,"2",Saldos_No_Util!Q:Q,'Resumen PE'!S15),"-") -> - | V15: =+IFERROR(T15*U15,"-") -> - | W15: =+IFERROR(SUMIFS(Saldos_No_Util!O:O,Saldos_No_Util!K:K,"2",Saldos_No_Util!Q:Q,'Resumen PE'!S15)/$E$4,"-") -> 0
J16: Documentos descontados | K16: =+SUMIFS('Cartera_Viva-Otros'!AM:AM,'Cartera_Viva-Otros'!AO:AO,'Resumen PE'!J16,'Cartera_Viva-Otros'!P:P,"F")/$E$4 -> 0 | M16: Documentos descontados | N16: =+SUMIFS('Cartera_Viva-Otros'!AN:AN,'Cartera_Viva-Otros'!AL:AL,"1",'Cartera_Viva-Otros'!P:P,"F",'Cartera_Viva-Otros'!AO:AO,'Resumen PE'!M16)/$E$4 -> 0 | O16: =IFERROR(AVERAGEIFS('Cartera_Viva-Otros'!AJ:AJ,'Cartera_Viva-Otros'!AL:AL,"1",'Cartera_Viva-Otros'!P:P,"F",'Cartera_Viva-Otros'!AO:AO,'Resumen PE'!M16),"-") -> - | P16: =IFERROR(AVERAGEIFS('Cartera_Viva-Otros'!AK:AK,'Cartera_Viva-Otros'!AL:AL,"1",'Cartera_Viva-Otros'!P:P,"F",'Cartera_Viva-Otros'!AO:AO,'Resumen PE'!M16),"-") -> - | Q16: =+SUMIFS('Cartera_Viva-Otros'!AM:AM,'Cartera_Viva-Otros'!AL:AL,"1",'Cartera_Viva-Otros'!P:P,"F",'Cartera_Viva-Otros'!AO:AO,'Resumen PE'!M16)/$E$4 -> 0 | S16: Stage 3
J17: Saldo no utilizado TC | K17: =+SUMIFS(Saldos_No_Util!G:G,Saldos_No_Util!P:P,"F",Saldos_No_Util!Q:Q,J17)/$E$4 -> 152.99962 | M17: Saldo no utilizado TC | N17: =+SUMIFS(Saldos_No_Util!O:O,Saldos_No_Util!K:K,"1",Saldos_No_Util!P:P,"F",Saldos_No_Util!Q:Q,'Resumen PE'!M17)/$E$4 -> 0.80985861 | O17: =IFERROR(AVERAGEIFS(Saldos_No_Util!L:L,Saldos_No_Util!K:K,"1",Saldos_No_Util!P:P,"F",Saldos_No_Util!Q:Q,'Resumen PE'!M17),0) -> 0.015 | P17: =IFERROR(AVERAGEIFS(Saldos_No_Util!M:M,Saldos_No_Util!K:K,"1",Saldos_No_Util!P:P,"F",Saldos_No_Util!Q:Q,'Resumen PE'!M17),0) -> 0.66499986 | Q17: =+SUMIFS(Saldos_No_Util!G:G,Saldos_No_Util!K:K,"1",Saldos_No_Util!P:P,"F",Saldos_No_Util!Q:Q,'Resumen PE'!M17)/$E$4 -> 152.28764 | S17: Saldo no utilizado TC | T17: =+SUMIFS(Saldos_No_Util!G:G,Saldos_No_Util!K:K,"3",Saldos_No_Util!Q:Q,'Resumen PE'!S17)/$E$4 -> 0.7119747 | U17: =+IFERROR(AVERAGEIFS(Saldos_No_Util!N:N,Saldos_No_Util!K:K,"3",Saldos_No_Util!Q:Q,'Resumen PE'!S17),"-") -> 0.4 | V17: =+IFERROR(T17*U17,"-") -> 0.28478988 | W17: =+IFERROR(SUMIFS(Saldos_No_Util!O:O,Saldos_No_Util!K:K,"3",Saldos_No_Util!Q:Q,'Resumen PE'!S17)/$E$4,"-") -> 0.35015728
J18: Saldo no utilizado ACC | K18: =+SUMIFS(Saldos_No_Util!G:G,Saldos_No_Util!P:P,"F",Saldos_No_Util!Q:Q,J18)/$E$4 -> 0 | M18: Saldo no utilizado ACC | N18: =+SUMIFS(Saldos_No_Util!O:O,Saldos_No_Util!K:K,"1",Saldos_No_Util!P:P,"F",Saldos_No_Util!Q:Q,'Resumen PE'!M18)/$E$4 -> 0 | O18: =IFERROR(AVERAGEIFS(Saldos_No_Util!L:L,Saldos_No_Util!K:K,"1",Saldos_No_Util!P:P,"F",Saldos_No_Util!Q:Q,'Resumen PE'!M18),"-") -> - | P18: =IFERROR(AVERAGEIFS(Saldos_No_Util!M:M,Saldos_No_Util!K:K,"1",Saldos_No_Util!P:P,"F",Saldos_No_Util!Q:Q,'Resumen PE'!M18),"-") -> - | Q18: =+SUMIFS(Saldos_No_Util!G:G,Saldos_No_Util!K:K,"1",Saldos_No_Util!P:P,"F",Saldos_No_Util!Q:Q,'Resumen PE'!M18)/$E$4 -> 0 | S18: Saldo no utilizado ACC | T18: =+SUMIFS(Saldos_No_Util!G:G,Saldos_No_Util!K:K,"3",Saldos_No_Util!Q:Q,'Resumen PE'!S18)/$E$4 -> 0 | U18: =+IFERROR(AVERAGEIFS(Saldos_No_Util!N:N,Saldos_No_Util!K:K,"3",Saldos_No_Util!Q:Q,'Resumen PE'!S18),"-") -> - | V18: =+IFERROR(T18*U18,"-") -> - | W18: =+IFERROR(SUMIFS(Saldos_No_Util!O:O,Saldos_No_Util!K:K,"3",Saldos_No_Util!Q:Q,'Resumen PE'!S18)/$E$4,"-") -> 0
J19: Otros | K19: =+SUMIFS('Cartera_Viva-Otros'!AM:AM,'Cartera_Viva-Otros'!AO:AO,"IVA Debito Fiscal no Cobrados",'Cartera_Viva-Otros'!P:P,"F")/$E$4 -> 0 | M19: Otros | N19: =+SUMIFS('Cartera_Viva-Otros'!AN:AN,'Cartera_Viva-Otros'!AL:AL,"1",'Cartera_Viva-Otros'!P:P,"F",'Cartera_Viva-Otros'!AO:AO,"IVA Debito Fiscal no Cobrados")/$E$4 -> 0 | O19: =IFERROR(AVERAGEIFS('Cartera_Viva-Otros'!AJ:AJ,'Cartera_Viva-Otros'!AL:AL,"1",'Cartera_Viva-Otros'!P:P,"F",'Cartera_Viva-Otros'!AO:AO,"IVA Debito Fiscal no Cobrados"),"-") -> - | P19: =IFERROR(AVERAGEIFS('Cartera_Viva-Otros'!AK:AK,'Cartera_Viva-Otros'!AL:AL,"1",'Cartera_Viva-Otros'!P:P,"F",'Cartera_Viva-Otros'!AO:AO,"IVA Debito Fiscal no Cobrados"),"-") -> - | Q19: =+SUMIFS('Cartera_Viva-Otros'!AM:AM,'Cartera_Viva-Otros'!AL:AL,"1",'Cartera_Viva-Otros'!P:P,"F",'Cartera_Viva-Otros'!AO:AO,"IVA Debito Fiscal no Cobrados")/$E$4 -> 0
J20: PCE Cartera mayorista | K20: =+(SUMIFS('Cartera_Viva-Otros'!AN:AN,'Cartera_Viva-Otros'!P:P,"J")+SUMIFS(Saldos_No_Util!O:O,Saldos_No_Util!P:P,"J")+SUM('Cartera_Viva-Calls'!AJ7:AJ8))/$E$4 -> 0.18841405 | M20: Cartera Mayorista | N20: =+(SUMIFS('Cartera_Viva-Otros'!AN:AN,'Cartera_Viva-Otros'!AL:AL,"1",'Cartera_Viva-Otros'!P:P,"J")+SUMIFS(Saldos_No_Util!O:O,Saldos_No_Util!P:P,"J",Saldos_No_Util!K:K,"1")+SUMIF('Cartera_Viva-Calls'!AF:AF,"1",'Cartera_Viva-Calls'!AJ:AJ))/$E$4 -> 0.18841405 | O20: =AVERAGEIFS('Cartera_Viva-Otros'!AJ:AJ,'Cartera_Viva-Otros'!AL:AL,"1",'Cartera_Viva-Otros'!P:P,"J") -> #DIV/0! | P20: =AVERAGEIFS('Cartera_Viva-Otros'!AK:AK,'Cartera_Viva-Otros'!AL:AL,"1",'Cartera_Viva-Otros'!P:P,"J") -> #DIV/0! | Q20: =+(SUMIFS('Cartera_Viva-Otros'!AM:AM,'Cartera_Viva-Otros'!AL:AL,"1",'Cartera_Viva-Otros'!P:P,"J")+SUMIFS(Saldos_No_Util!G:G,Saldos_No_Util!P:P,"J",Saldos_No_Util!K:K,"1")+SUMIF('Cartera_Viva-Calls'!AF:AF,"1",'Cartera_Viva-Calls'!AC:AC))/$E$4 -> 927.99418
J21: EAD Cartera mayorista | K21: =+(SUMIFS('Cartera_Viva-Otros'!AM:AM,'Cartera_Viva-Otros'!P:P,"J")+SUMIFS(Saldos_No_Util!G:G,Saldos_No_Util!P:P,"J")+SUM('Cartera_Viva-Calls'!AC7:AC8))/$E$4 -> 927.99418 | M21: Tarjetas_de_Crédito | N21: =+SUMIFS('Cartera_Viva-Otros'!AN:AN,'Cartera_Viva-Otros'!AL:AL,"1",'Cartera_Viva-Otros'!P:P,"J",'Cartera_Viva-Otros'!AO:AO,'Resumen PE'!M21)/$E$4 -> 0 | O21: =IFERROR(AVERAGEIFS('Cartera_Viva-Otros'!AJ:AJ,'Cartera_Viva-Otros'!AL:AL,"1",'Cartera_Viva-Otros'!P:P,"J",'Cartera_Viva-Otros'!AO:AO,'Resumen PE'!M21),"-") -> - | P21: =IFERROR(AVERAGEIFS('Cartera_Viva-Otros'!AK:AK,'Cartera_Viva-Otros'!AL:AL,"1",'Cartera_Viva-Otros'!P:P,"J",'Cartera_Viva-Otros'!AO:AO,'Resumen PE'!M21),"-") -> - | Q21: =+SUMIFS('Cartera_Viva-Otros'!AM:AM,'Cartera_Viva-Otros'!AL:AL,"1",'Cartera_Viva-Otros'!P:P,"J",'Cartera_Viva-Otros'!AO:AO,'Resumen PE'!M12)/$E$4 -> 0
J22: Tarjetas_de_Crédito | K22: =+SUMIFS('Cartera_Viva-Otros'!AM:AM,'Cartera_Viva-Otros'!AO:AO,'Resumen PE'!J22,'Cartera_Viva-Otros'!P:P,"J")/$E$4 -> 0 | M22: Prestamos Personales | N22: =+SUMIFS('Cartera_Viva-Otros'!AN:AN,'Cartera_Viva-Otros'!AL:AL,"1",'Cartera_Viva-Otros'!P:P,"J",'Cartera_Viva-Otros'!AO:AO,'Resumen PE'!M22)/$E$4 -> 0 | O22: =IFERROR(AVERAGEIFS('Cartera_Viva-Otros'!AJ:AJ,'Cartera_Viva-Otros'!AL:AL,"1",'Cartera_Viva-Otros'!P:P,"J",'Cartera_Viva-Otros'!AO:AO,'Resumen PE'!M22),"-") -> - | P22: =IFERROR(AVERAGEIFS('Cartera_Viva-Otros'!AK:AK,'Cartera_Viva-Otros'!AL:AL,"1",'Cartera_Viva-Otros'!P:P,"J",'Cartera_Viva-Otros'!AO:AO,'Resumen PE'!M22),"-") -> - | Q22: =+SUMIFS('Cartera_Viva-Otros'!AM:AM,'Cartera_Viva-Otros'!AL:AL,"1",'Cartera_Viva-Otros'!P:P,"J",'Cartera_Viva-Otros'!AO:AO,'Resumen PE'!M13)/$E$4 -> 0
J23: Prestamos Personales | K23: =+SUMIFS('Cartera_Viva-Otros'!AM:AM,'Cartera_Viva-Otros'!AO:AO,'Resumen PE'!J23,'Cartera_Viva-Otros'!P:P,"J")/$E$4 -> 0 | M23: Prestamos a Sola Firma | N23: =+SUMIFS('Cartera_Viva-Otros'!AN:AN,'Cartera_Viva-Otros'!AL:AL,"1",'Cartera_Viva-Otros'!P:P,"J",'Cartera_Viva-Otros'!AO:AO,'Resumen PE'!M23)/$E$4 -> 0 | O23: =IFERROR(AVERAGEIFS('Cartera_Viva-Otros'!AJ:AJ,'Cartera_Viva-Otros'!AL:AL,"1",'Cartera_Viva-Otros'!P:P,"J",'Cartera_Viva-Otros'!AO:AO,'Resumen PE'!M23),"-") -> - | P23: =IFERROR(AVERAGEIFS('Cartera_Viva-Otros'!AK:AK,'Cartera_Viva-Otros'!AL:AL,"1",'Cartera_Viva-Otros'!P:P,"J",'Cartera_Viva-Otros'!AO:AO,'Resumen PE'!M23),"-") -> - | Q23: =+SUMIFS('Cartera_Viva-Otros'!AM:AM,'Cartera_Viva-Otros'!AL:AL,"1",'Cartera_Viva-Otros'!P:P,"J",'Cartera_Viva-Otros'!AO:AO,'Resumen PE'!M14)/$E$4 -> 0
J24: Prestamos a Sola Firma | K24: =+SUMIFS('Cartera_Viva-Otros'!AM:AM,'Cartera_Viva-Otros'!AO:AO,'Resumen PE'!J24,'Cartera_Viva-Otros'!P:P,"J")/$E$4 -> 0 | M24: ACC | N24: =+SUMIFS('Cartera_Viva-Otros'!AN:AN,'Cartera_Viva-Otros'!AL:AL,"1",'Cartera_Viva-Otros'!P:P,"J",'Cartera_Viva-Otros'!AO:AO,'Resumen PE'!M24)/$E$4 -> 0 | O24: =IFERROR(AVERAGEIFS('Cartera_Viva-Otros'!AJ:AJ,'Cartera_Viva-Otros'!AL:AL,"1",'Cartera_Viva-Otros'!P:P,"J",'Cartera_Viva-Otros'!AO:AO,'Resumen PE'!M24),"-") -> - | P24: =IFERROR(AVERAGEIFS('Cartera_Viva-Otros'!AK:AK,'Cartera_Viva-Otros'!AL:AL,"1",'Cartera_Viva-Otros'!P:P,"J",'Cartera_Viva-Otros'!AO:AO,'Resumen PE'!M24),"-") -> - | Q24: =+SUMIFS('Cartera_Viva-Otros'!AM:AM,'Cartera_Viva-Otros'!AL:AL,"1",'Cartera_Viva-Otros'!P:P,"J",'Cartera_Viva-Otros'!AO:AO,'Resumen PE'!M15)/$E$4 -> 0
J25: ACC | K25: =+SUMIFS('Cartera_Viva-Otros'!AM:AM,'Cartera_Viva-Otros'!AO:AO,'Resumen PE'!J25,'Cartera_Viva-Otros'!P:P,"J")/$E$4 -> 0 | M25: Documentos descontados | N25: =+SUMIFS('Cartera_Viva-Otros'!AN:AN,'Cartera_Viva-Otros'!AL:AL,"1",'Cartera_Viva-Otros'!P:P,"J",'Cartera_Viva-Otros'!AO:AO,'Resumen PE'!M25)/$E$4 -> 0 | O25: =IFERROR(AVERAGEIFS('Cartera_Viva-Otros'!AJ:AJ,'Cartera_Viva-Otros'!AL:AL,"1",'Cartera_Viva-Otros'!P:P,"J",'Cartera_Viva-Otros'!AO:AO,'Resumen PE'!M25),"-") -> - | P25: =IFERROR(AVERAGEIFS('Cartera_Viva-Otros'!AK:AK,'Cartera_Viva-Otros'!AL:AL,"1",'Cartera_Viva-Otros'!P:P,"J",'Cartera_Viva-Otros'!AO:AO,'Resumen PE'!M25),"-") -> - | Q25: =+SUMIFS('Cartera_Viva-Otros'!AM:AM,'Cartera_Viva-Otros'!AL:AL,"1",'Cartera_Viva-Otros'!P:P,"J",'Cartera_Viva-Otros'!AO:AO,'Resumen PE'!M16)/$E$4 -> 0
J26: Documentos descontados | K26: =+SUMIFS('Cartera_Viva-Otros'!AM:AM,'Cartera_Viva-Otros'!AO:AO,'Resumen PE'!J26,'Cartera_Viva-Otros'!P:P,"J")/$E$4 -> 0 | M26: Saldo no utilizado TC | N26: =+SUMIFS(Saldos_No_Util!O:O,Saldos_No_Util!K:K,"1",Saldos_No_Util!P:P,"J",Saldos_No_Util!Q:Q,'Resumen PE'!M26)/$E$4 -> 0.085311825 | O26: =IFERROR(AVERAGEIFS(Saldos_No_Util!L:L,Saldos_No_Util!K:K,"1",Saldos_No_Util!P:P,"J",Saldos_No_Util!Q:Q,'Resumen PE'!M26),0) -> 0.015 | P26: =IFERROR(AVERAGEIFS(Saldos_No_Util!M:M,Saldos_No_Util!K:K,"1",Saldos_No_Util!P:P,"J",Saldos_No_Util!Q:Q,'Resumen PE'!M26),0) -> 0.66499986 | Q26: =+SUMIFS(Saldos_No_Util!G:G,Saldos_No_Util!K:K,"1",Saldos_No_Util!P:P,"J",Saldos_No_Util!Q:Q,'Resumen PE'!M26)/$E$4 -> 16.042228
J27: Saldo no utilizado TC | K27: =+SUMIFS(Saldos_No_Util!G:G,Saldos_No_Util!P:P,"J",Saldos_No_Util!Q:Q,J27)/$E$4 -> 16.042228 | M27: Saldo no utilizado ACC | N27: =+SUMIFS(Saldos_No_Util!O:O,Saldos_No_Util!K:K,"1",Saldos_No_Util!P:P,"J",Saldos_No_Util!Q:Q,'Resumen PE'!M27)/$E$4 -> 0.069973463 | O27: =IFERROR(AVERAGEIFS(Saldos_No_Util!L:L,Saldos_No_Util!K:K,"1",Saldos_No_Util!P:P,"J",Saldos_No_Util!Q:Q,'Resumen PE'!M27),"-") -> 0.015 | P27: =IFERROR(AVERAGEIFS(Saldos_No_Util!M:M,Saldos_No_Util!K:K,"1",Saldos_No_Util!P:P,"J",Saldos_No_Util!Q:Q,'Resumen PE'!M27),"-") -> 0.66499986 | Q27: =+SUMIFS(Saldos_No_Util!G:G,Saldos_No_Util!K:K,"1",Saldos_No_Util!P:P,"J",Saldos_No_Util!Q:Q,'Resumen PE'!M27)/$E$4 -> 11.526606
J28: Saldo no utilizado ACC | K28: =+SUMIFS(Saldos_No_Util!G:G,Saldos_No_Util!P:P,"J",Saldos_No_Util!Q:Q,J28)/$E$4 -> 11.526606 | M28: Call Financiero | N28: =+SUM('Cartera_Viva-Calls'!AJ:AJ)/1000000 -> 0.033128766 | O28: ='Cartera_Viva-Calls'!AH7 -> 5.5326856e-05 | P28: =+'Cartera_Viva-Calls'!AI7 -> 0.66499986 | Q28: =+SUM('Cartera_Viva-Calls'!AC:AC)/1000000 -> 900.42534
J29: Call Financiero | K29: =+SUM('Cartera_Viva-Calls'!AC7:AC8)/'Resumen PE'!$E$4 -> 900.42534 | M29: Otros | N29: =+SUMIFS('Cartera_Viva-Otros'!AN:AN,'Cartera_Viva-Otros'!AL:AL,"1",'Cartera_Viva-Otros'!P:P,"J",'Cartera_Viva-Otros'!AO:AO,"IVA Debito Fiscal no Cobrados")/$E$4 -> 0 | O29: =IFERROR(AVERAGEIFS('Cartera_Viva-Otros'!AJ:AJ,'Cartera_Viva-Otros'!AL:AL,"1",'Cartera_Viva-Otros'!P:P,"J",'Cartera_Viva-Otros'!AO:AO,"IVA Debito Fiscal no Cobrados"),"-") -> - | P29: =IFERROR(AVERAGEIFS('Cartera_Viva-Otros'!AK:AK,'Cartera_Viva-Otros'!AL:AL,"1",'Cartera_Viva-Otros'!P:P,"J",'Cartera_Viva-Otros'!AO:AO,"IVA Debito Fiscal no Cobrados"),"-") -> - | Q29: =+SUMIFS('Cartera_Viva-Otros'!AM:AM,'Cartera_Viva-Otros'!AL:AL,"1",'Cartera_Viva-Otros'!P:P,"J",'Cartera_Viva-Otros'!AO:AO,"IVA Debito Fiscal no Cobrados")/$E$4 -> 0
J30: Otros | K30: =+SUMIFS('Cartera_Viva-Otros'!AM:AM,'Cartera_Viva-Otros'!AO:AO,"IVA Debito Fiscal no Cobrados",'Cartera_Viva-Otros'!P:P,"J")/$E$4 -> 0 | M30: Stage 2
J31: PCE Total | K31: =+K10+K20 -> 1.3484299 | M31: Cartera Minorista | N31: =+(SUMIFS('Cartera_Viva-Otros'!AN:AN,'Cartera_Viva-Otros'!AL:AL,"2",'Cartera_Viva-Otros'!P:P,"F")+SUMIFS(Saldos_No_Util!O:O,Saldos_No_Util!K:K,"2",Saldos_No_Util!P:P,"F"))/$E$4 -> 0 | O31: =IFERROR(AVERAGEIFS('Cartera_Viva-Otros'!AJ:AJ,'Cartera_Viva-Otros'!AL:AL,"2",'Cartera_Viva-Otros'!P:P,"F"),0) -> 0 | P31: =IFERROR(AVERAGEIFS('Cartera_Viva-Otros'!AK:AK,'Cartera_Viva-Otros'!AL:AL,"2",'Cartera_Viva-Otros'!P:P,"F"),0) -> 0 | Q31: =+(SUMIFS('Cartera_Viva-Otros'!AM:AM,'Cartera_Viva-Otros'!AL:AL,"2",'Cartera_Viva-Otros'!P:P,"F")+SUMIFS(Saldos_No_Util!G:G,Saldos_No_Util!K:K,"2",Saldos_No_Util!P:P,"F"))/$E$4 -> 0
J32: EAD Total | K32: =+K11+K21 -> 1080.9938 | M32: Tarjetas_de_Crédito | N32: =+SUMIFS('Cartera_Viva-Otros'!AN:AN,'Cartera_Viva-Otros'!AL:AL,"2",'Cartera_Viva-Otros'!P:P,"F",'Cartera_Viva-Otros'!AO:AO,'Resumen PE'!M32)/$E$4 -> 0 | O32: =IFERROR(AVERAGEIFS('Cartera_Viva-Otros'!AJ:AJ,'Cartera_Viva-Otros'!AL:AL,"2",'Cartera_Viva-Otros'!P:P,"F",'Cartera_Viva-Otros'!AO:AO,'Resumen PE'!M32),"-") -> - | P32: =IFERROR(AVERAGEIFS('Cartera_Viva-Otros'!AK:AK,'Cartera_Viva-Otros'!AL:AL,"2",'Cartera_Viva-Otros'!P:P,"F",'Cartera_Viva-Otros'!AO:AO,'Resumen PE'!M32),"-") -> - | Q32: =+SUMIFS('Cartera_Viva-Otros'!AM:AM,'Cartera_Viva-Otros'!AL:AL,"2",'Cartera_Viva-Otros'!P:P,"F",'Cartera_Viva-Otros'!AO:AO,'Resumen PE'!M32)/$E$4 -> 0
M33: Prestamos Personales | N33: =+SUMIFS('Cartera_Viva-Otros'!AN:AN,'Cartera_Viva-Otros'!AL:AL,"2",'Cartera_Viva-Otros'!P:P,"F",'Cartera_Viva-Otros'!AO:AO,'Resumen PE'!M33)/$E$4 -> 0 | O33: =IFERROR(AVERAGEIFS('Cartera_Viva-Otros'!AJ:AJ,'Cartera_Viva-Otros'!AL:AL,"2",'Cartera_Viva-Otros'!P:P,"F",'Cartera_Viva-Otros'!AO:AO,'Resumen PE'!M33),"-") -> - | P33: =IFERROR(AVERAGEIFS('Cartera_Viva-Otros'!AK:AK,'Cartera_Viva-Otros'!AL:AL,"2",'Cartera_Viva-Otros'!P:P,"F",'Cartera_Viva-Otros'!AO:AO,'Resumen PE'!M33),"-") -> - | Q33: =+SUMIFS('Cartera_Viva-Otros'!AM:AM,'Cartera_Viva-Otros'!AL:AL,"2",'Cartera_Viva-Otros'!P:P,"F",'Cartera_Viva-Otros'!AO:AO,'Resumen PE'!M33)/$E$4 -> 0
M34: Prestamos a Sola Firma | N34: =+SUMIFS('Cartera_Viva-Otros'!AN:AN,'Cartera_Viva-Otros'!AL:AL,"2",'Cartera_Viva-Otros'!P:P,"F",'Cartera_Viva-Otros'!AO:AO,'Resumen PE'!M34)/$E$4 -> 0 | O34: =IFERROR(AVERAGEIFS('Cartera_Viva-Otros'!AJ:AJ,'Cartera_Viva-Otros'!AL:AL,"2",'Cartera_Viva-Otros'!P:P,"F",'Cartera_Viva-Otros'!AO:AO,'Resumen PE'!M34),"-") -> - | P34: =IFERROR(AVERAGEIFS('Cartera_Viva-Otros'!AK:AK,'Cartera_Viva-Otros'!AL:AL,"2",'Cartera_Viva-Otros'!P:P,"F",'Cartera_Viva-Otros'!AO:AO,'Resumen PE'!M34),"-") -> - | Q34: =+SUMIFS('Cartera_Viva-Otros'!AM:AM,'Cartera_Viva-Otros'!AL:AL,"2",'Cartera_Viva-Otros'!P:P,"F",'Cartera_Viva-Otros'!AO:AO,'Resumen PE'!M34)/$E$4 -> 0
M35: ACC | N35: =+SUMIFS('Cartera_Viva-Otros'!AN:AN,'Cartera_Viva-Otros'!AL:AL,"2",'Cartera_Viva-Otros'!P:P,"F",'Cartera_Viva-Otros'!AO:AO,'Resumen PE'!M35)/$E$4 -> 0 | O35: =IFERROR(AVERAGEIFS('Cartera_Viva-Otros'!AJ:AJ,'Cartera_Viva-Otros'!AL:AL,"2",'Cartera_Viva-Otros'!P:P,"F",'Cartera_Viva-Otros'!AO:AO,'Resumen PE'!M35),"-") -> - | P35: =IFERROR(AVERAGEIFS('Cartera_Viva-Otros'!AK:AK,'Cartera_Viva-Otros'!AL:AL,"2",'Cartera_Viva-Otros'!P:P,"F",'Cartera_Viva-Otros'!AO:AO,'Resumen PE'!M35),"-") -> - | Q35: =+SUMIFS('Cartera_Viva-Otros'!AM:AM,'Cartera_Viva-Otros'!AL:AL,"2",'Cartera_Viva-Otros'!P:P,"F",'Cartera_Viva-Otros'!AO:AO,'Resumen PE'!M35)/$E$4 -> 0
M36: Documentos descontados | N36: =+SUMIFS('Cartera_Viva-Otros'!AN:AN,'Cartera_Viva-Otros'!AL:AL,"2",'Cartera_Viva-Otros'!P:P,"F",'Cartera_Viva-Otros'!AO:AO,'Resumen PE'!M36)/$E$4 -> 0 | O36: =IFERROR(AVERAGEIFS('Cartera_Viva-Otros'!AJ:AJ,'Cartera_Viva-Otros'!AL:AL,"2",'Cartera_Viva-Otros'!P:P,"F",'Cartera_Viva-Otros'!AO:AO,'Resumen PE'!M36),"-") -> - | P36: =IFERROR(AVERAGEIFS('Cartera_Viva-Otros'!AK:AK,'Cartera_Viva-Otros'!AL:AL,"2",'Cartera_Viva-Otros'!P:P,"F",'Cartera_Viva-Otros'!AO:AO,'Resumen PE'!M36),"-") -> - | Q36: =+SUMIFS('Cartera_Viva-Otros'!AM:AM,'Cartera_Viva-Otros'!AL:AL,"2",'Cartera_Viva-Otros'!P:P,"F",'Cartera_Viva-Otros'!AO:AO,'Resumen PE'!M36)/$E$4 -> 0
M37: Saldo no utilizado TC | N37: =+SUMIFS(Saldos_No_Util!O:O,Saldos_No_Util!K:K,"2",Saldos_No_Util!P:P,"F",Saldos_No_Util!Q:Q,'Resumen PE'!M37)/$E$4 -> 0 | O37: =IFERROR(AVERAGEIFS(Saldos_No_Util!L:L,Saldos_No_Util!K:K,"2",Saldos_No_Util!P:P,"F",Saldos_No_Util!Q:Q,'Resumen PE'!M37),0) -> 0 | P37: =IFERROR(AVERAGEIFS(Saldos_No_Util!M:M,Saldos_No_Util!K:K,"2",Saldos_No_Util!P:P,"F",Saldos_No_Util!Q:Q,'Resumen PE'!M37),0) -> 0 | Q37: =+SUMIFS(Saldos_No_Util!G:G,Saldos_No_Util!K:K,"2",Saldos_No_Util!P:P,"F",Saldos_No_Util!Q:Q,'Resumen PE'!M37)/$E$4 -> 0
M38: Saldo no utilizado ACC | N38: =+SUMIFS(Saldos_No_Util!O:O,Saldos_No_Util!K:K,"2",Saldos_No_Util!P:P,"F",Saldos_No_Util!Q:Q,'Resumen PE'!M38)/$E$4 -> 0 | O38: =IFERROR(AVERAGEIFS(Saldos_No_Util!L:L,Saldos_No_Util!K:K,"2",Saldos_No_Util!P:P,"F",Saldos_No_Util!Q:Q,'Resumen PE'!M38),"-") -> - | P38: =IFERROR(AVERAGEIFS(Saldos_No_Util!M:M,Saldos_No_Util!K:K,"2",Saldos_No_Util!P:P,"F",Saldos_No_Util!Q:Q,'Resumen PE'!M38),"-") -> - | Q38: =+SUMIFS(Saldos_No_Util!G:G,Saldos_No_Util!K:K,"2",Saldos_No_Util!P:P,"F",Saldos_No_Util!Q:Q,'Resumen PE'!M38)/$E$4 -> 0
M39: Otros | N39: =+SUMIFS('Cartera_Viva-Otros'!AN:AN,'Cartera_Viva-Otros'!AL:AL,"2",'Cartera_Viva-Otros'!P:P,"F",'Cartera_Viva-Otros'!AO:AO,'Resumen PE'!M39)/$E$4 -> 0 | O39: =IFERROR(AVERAGEIFS('Cartera_Viva-Otros'!AJ:AJ,'Cartera_Viva-Otros'!AL:AL,"2",'Cartera_Viva-Otros'!P:P,"F",'Cartera_Viva-Otros'!AO:AO,"IVA Debito Fiscal no Cobrados"),"-") -> - | P39: =IFERROR(AVERAGEIFS('Cartera_Viva-Otros'!AK:AK,'Cartera_Viva-Otros'!AL:AL,"2",'Cartera_Viva-Otros'!P:P,"F",'Cartera_Viva-Otros'!AO:AO,"IVA Debito Fiscal no Cobrados"),"-") -> - | Q39: =+SUMIFS('Cartera_Viva-Otros'!AM:AM,'Cartera_Viva-Otros'!AL:AL,"2",'Cartera_Viva-Otros'!P:P,"F",'Cartera_Viva-Otros'!AO:AO,"IVA Debito Fiscal no Cobrados")/$E$4 -> 0
M40: Cartera Mayorista | N40: =+(SUMIFS('Cartera_Viva-Otros'!AN:AN,'Cartera_Viva-Otros'!AL:AL,"2",'Cartera_Viva-Otros'!P:P,"J")+SUMIFS(Saldos_No_Util!O:O,Saldos_No_Util!P:P,"J",Saldos_No_Util!K:K,"2")+SUMIF('Cartera_Viva-Calls'!AF7,"2",'Cartera_Viva-Calls'!AJ7))/$E$4 -> 0 | O40: =IFERROR(AVERAGEIFS('Cartera_Viva-Otros'!AJ:AJ,'Cartera_Viva-Otros'!AL:AL,"2",'Cartera_Viva-Otros'!P:P,"J"),"-") -> - | P40: =IFERROR(AVERAGEIFS('Cartera_Viva-Otros'!AK:AK,'Cartera_Viva-Otros'!AL:AL,"2",'Cartera_Viva-Otros'!P:P,"J"),"-") -> - | Q40: =+(SUMIFS('Cartera_Viva-Otros'!AM:AM,'Cartera_Viva-Otros'!AL:AL,"2",'Cartera_Viva-Otros'!P:P,"J")+SUMIFS(Saldos_No_Util!G:G,Saldos_No_Util!P:P,"J",Saldos_No_Util!K:K,"2")+SUMIF('Cartera_Viva-Calls'!AF7,"2",'Cartera_Viva-Calls'!AC7))/$E$4 -> 0
M41: Tarjetas_de_Crédito | N41: =+SUMIFS('Cartera_Viva-Otros'!AN:AN,'Cartera_Viva-Otros'!AL:AL,"2",'Cartera_Viva-Otros'!P:P,"J",'Cartera_Viva-Otros'!AO:AO,'Resumen PE'!M41)/$E$4 -> 0 | O41: =IFERROR(AVERAGEIFS('Cartera_Viva-Otros'!AJ:AJ,'Cartera_Viva-Otros'!AL:AL,"2",'Cartera_Viva-Otros'!P:P,"J",'Cartera_Viva-Otros'!AO:AO,'Resumen PE'!M41),"-") -> - | P41: =IFERROR(AVERAGEIFS('Cartera_Viva-Otros'!AK:AK,'Cartera_Viva-Otros'!AL:AL,"2",'Cartera_Viva-Otros'!P:P,"J",'Cartera_Viva-Otros'!AO:AO,'Resumen PE'!M41),"-") -> - | Q41: =+SUMIFS('Cartera_Viva-Otros'!AM:AM,'Cartera_Viva-Otros'!AL:AL,"2",'Cartera_Viva-Otros'!P:P,"J",'Cartera_Viva-Otros'!AO:AO,'Resumen PE'!M32)/$E$4 -> 0
...

Sheet Cartera_Viva-Otros
A1: BCRubr | B1: BCMda | C1: BCCta | D1: BCOper | E1: BCSbOp | F1: BCFech | G1: BCFVto | H1: BCFVal | I1: BCPlaz | J1: BCTTasa | K1: BCTasa | L1: BCTDia | M1: BCTAno | N1: BCResi | O1: BCCate | P1: BCActi | Q1: BCTiCu | R1: BCFAtr | S1: BCSdOr | T1: BCSdMN | U1: BCSdUS | V1: BCSdMO | W1: BCInt | X1: BCPrev | Y1: BCCate sin esp | Z1: Situación BCRA | AA1: rubros_considerados | AB1: rubros_considerados_2 | AC1: Deuda+int | AD1: PD | AE1: PD_diaria | AF1: Plazo1 | AG1: Plazo2 | AH1: Min(Plazo;365) | AI1: Plazo Prom | AJ1: PD o 100% | AK1: LGD | AL1: Stage | AM1: EAD | AN1: PE | AO1: Producto | AQ1: FECHA DE CALCULO | AR1: =$F$2 -> 46142
A2: 131709001 | B2: 80 | C2: 6206 | D2: 3563 | E2: 0 | F2: 46142 | G2: 46417 | H2: 46052 | I2: 365 | J2: 2 | K2: 73 | L2: 0 | M2: 0 | N2: S | O2: Sit.Normal | P2: 466 | Q2: J | R2: 46136 | S2: 0 | T2: -22482.8 | U2: -16.28 | V2: -22482.8 | W2: 0 | X2: 224.83 | Y2: =TRIM(O2) -> Sit.Normal | Z2: =IF(Y2="Sit.Normal",1,IF(Y2="Riesgo potencia",2,IF(Y2="Con Problemas",3,IF(Y2="Alto Riesgo",4,IF(Y2="Irrecuperable",5,IF(Y2="Irrec Disp Tecn",6,IF(Y2="Sin identificación",0,""))))))) -> 1 | AB2: =VLOOKUP(A2,rubros_a_considerar!$A$2:$A$13,1,FALSE) -> 131709001 | AC2: =T2+W2 -> -22482.8 | AD2: =IF(Z2<=1,Diccionario!$M$2,Diccionario!$M$3) -> 0.015 | AE2: =1-(1-AD2)^(1/365) -> 4.140637e-05 | AF2: =+IFERROR(G2-$AR$1,0) -> 275 | AG2: =+IF(AF2<=0,10*365,AF2) -> 275 | AH2: =+IF(Z2<=1,MIN(AG2,365),AG2) -> 275 | AI2: =+(1-(AG2+1)*(1-AE2)^AG2+AG2*(1-AE2)^(AG2+1))/((1-(1-AE2)^AG2)*AE2)-0.5 -> 137.23905 | AJ2: =+IF(Z2<3,AD2,1) -> 0.015 | AK2: =IF(Z2<=3,Diccionario!$O$2,IF(Z2=4,Diccionario!$O$5,Diccionario!$O$6)) -> 0.66499986 | AL2: =+IF(Z2<=1,1,IF(Z2=2,2,3)) -> 1 | AM2: =+IF(AC2<0,-AC2,0) -> 22482.8 | AN2: =MIN(AJ2*AK2*AM2*(1+'[2]Pesos escenarios'!$F$8/2),AM2) -> 298.90621 | AO2: =IFERROR(VLOOKUP(A2,Diccionario!$C$2:$E$65,3,FALSE),"no") -> ACC
A3: 131709001 | B3: 80 | C3: 85455 | D3: 3560 | E3: 0 | F3: 46142 | G3: 46302 | H3: 45937 | I3: 365 | J3: 2 | K3: 73 | L3: 0 | M3: 0 | N3: S | O3: Sit.Normal | P3: 620 | Q3: J | R3: 46142 | S3: 0 | T3: -103456.1 | U3: -74.91 | V3: -103456.1 | W3: 0 | X3: 1034.56 | Y3: =TRIM(O3) -> Sit.Normal | Z3: =IF(Y3="Sit.Normal",1,IF(Y3="Riesgo potencia",2,IF(Y3="Con Problemas",3,IF(Y3="Alto Riesgo",4,IF(Y3="Irrecuperable",5,IF(Y3="Irrec Disp Tecn",6,IF(Y3="Sin identificación",0,""))))))) -> 1 | AB3: =VLOOKUP(A3,rubros_a_considerar!$A$2:$A$13,1,FALSE) -> 131709001 | AC3: =T3+W3 -> -103456.1 | AD3: =IF(Z3<=1,Diccionario!$M$2,Diccionario!$M$3) -> 0.015 | AE3: =1-(1-AD3)^(1/365) -> 4.140637e-05 | AF3: =+IFERROR(G3-$AR$1,0) -> 160 | AG3: =+IF(AF3<=0,10*365,AF3) -> 160 | AH3: =+IF(Z3<=1,MIN(AG3,365),AG3) -> 160 | AI3: =+(1-(AG3+1)*(1-AE3)^AG3+AG3*(1-AE3)^(AG3+1))/((1-(1-AE3)^AG3)*AE3)-0.5 -> 79.911668 | AJ3: =+IF(Z3<3,AD3,1) -> 0.015 | AK3: =IF(Z3<=3,Diccionario!$O$2,IF(Z3=4,Diccionario!$O$5,Diccionario!$O$6)) -> 0.66499986 | AL3: =+IF(Z3<=1,1,IF(Z3=2,2,3)) -> 1 | AM3: =+IF(AC3<0,-AC3,0) -> 103456.1 | AN3: =MIN(AJ3*AK3*AM3*(1+'[2]Pesos escenarios'!$F$8/2),AM3) -> 1375.4368 | AO3: =IFERROR(VLOOKUP(A3,Diccionario!$C$2:$E$65,3,FALSE),"no") -> ACC
A4: 131709001 | B4: 80 | C4: 59750 | D4: 3553 | E4: 0 | F4: 46142 | G4: 46235 | H4: 45870 | I4: 365 | J4: 2 | K4: 52 | L4: 0 | M4: 0 | N4: S | O4: Sit.Normal | P4: 103 | Q4: J | R4: 45797 | S4: 0 | T4: -7347455.2 | U4: -5320.02 | V4: -7347455.2 | W4: 0 | X4: 73474.55 | Y4: =TRIM(O4) -> Sit.Normal | Z4: =IF(Y4="Sit.Normal",1,IF(Y4="Riesgo potencia",2,IF(Y4="Con Problemas",3,IF(Y4="Alto Riesgo",4,IF(Y4="Irrecuperable",5,IF(Y4="Irrec Disp Tecn",6,IF(Y4="Sin identificación",0,""))))))) -> 1 | AB4: =VLOOKUP(A4,rubros_a_considerar!$A$2:$A$13,1,FALSE) -> 131709001 | AC4: =T4+W4 -> -7347455.2 | AD4: =IF(Z4<=1,Diccionario!$M$2,Diccionario!$M$3) -> 0.015 | AE4: =1-(1-AD4)^(1/365) -> 4.140637e-05 | AF4: =+IFERROR(G4-$AR$1,0) -> 93 | AG4: =+IF(AF4<=0,10*365,AF4) -> 93 | AH4: =+IF(Z4<=1,MIN(AG4,365),AG4) -> 93 | AI4: =+(1-(AG4+1)*(1-AE4)^AG4+AG4*(1-AE4)^(AG4+1))/((1-(1-AE4)^AG4)*AE4)-0.5 -> 46.470159 | AJ4: =+IF(Z4<3,AD4,1) -> 0.015 | AK4: =IF(Z4<=3,Diccionario!$O$2,IF(Z4=4,Diccionario!$O$5,Diccionario!$O$6)) -> 0.66499986 | AL4: =+IF(Z4<=1,1,IF(Z4=2,2,3)) -> 1 | AM4: =+IF(AC4<0,-AC4,0) -> 7347455.2 | AN4: =MIN(AJ4*AK4*AM4*(1+'[2]Pesos escenarios'!$F$8/2),AM4) -> 97683.562 | AO4: =IFERROR(VLOOKUP(A4,Diccionario!$C$2:$E$65,3,FALSE),"no") -> ACC
A5: 141154001 | B5: 80 | C5: 86152 | D5: 42805 | E5: 0 | F5: 46142 | G5: 1753-01-01 | H5: 46142 | I5: 0 | J5: 0 | K5: 0 | L5: 0 | M5: 0 | N5: S | O5: Sit.Normal | P5: 999 | Q5: F | R5: 46142 | S5: 0 | T5: -707.32 | U5: -0.51 | V5: -707.32 | W5: 0 | X5: 7.07 | Y5: =TRIM(O5) -> Sit.Normal | Z5: =IF(Y5="Sit.Normal",1,IF(Y5="Riesgo potencia",2,IF(Y5="Con Problemas",3,IF(Y5="Alto Riesgo",4,IF(Y5="Irrecuperable",5,IF(Y5="Irrec Disp Tecn",6,IF(Y5="Sin identificación",0,""))))))) -> 1 | AB5: =VLOOKUP(A5,rubros_a_considerar!$A$2:$A$13,1,FALSE) -> 141154001 | AC5: =T5+W5 -> -707.32 | AD5: =IF(Z5<=1,Diccionario!$M$2,Diccionario!$M$3) -> 0.015 | AE5: =1-(1-AD5)^(1/365) -> 4.140637e-05 | AF5: =+IFERROR(G5-$AR$1,0) -> 0 | AG5: =+IF(AF5<=0,10*365,AF5) -> 3650 | AH5: =+IF(Z5<=1,MIN(AG5,365),AG5) -> 365 | AI5: =+(1-(AG5+1)*(1-AE5)^AG5+AG5*(1-AE5)^(AG5+1))/((1-(1-AE5)^AG5)*AE5)-0.5 -> 1779.0468 | AJ5: =+IF(Z5<3,AD5,1) -> 0.015 | AK5: =IF(Z5<=3,Diccionario!$O$2,IF(Z5=4,Diccionario!$O$5,Diccionario!$O$6)) -> 0.66499986 | AL5: =+IF(Z5<=1,1,IF(Z5=2,2,3)) -> 1 | AM5: =+IF(AC5<0,-AC5,0) -> 707.32 | AN5: =MIN(AJ5*AK5*AM5*(1+'[2]Pesos escenarios'!$F$8/2),AM5) -> 9.4037372 | AO5: =IFERROR(VLOOKUP(A5,Diccionario!$C$2:$E$65,3,FALSE),"no") -> IVA Debito Fiscal no Cobrados
A6: 141154001 | B6: 80 | C6: 86563 | D6: 42806 | E6: 0 | F6: 46142 | G6: 1753-01-01 | H6: 46142 | I6: 0 | J6: 0 | K6: 0 | L6: 0 | M6: 0 | N6: S | O6: Sit.Normal | P6: 999 | Q6: F | R6: 46142 | S6: 0 | T6: -1108.73 | U6: -0.8 | V6: -1108.73 | W6: 0 | X6: 11.09 | Y6: =TRIM(O6) -> Sit.Normal | Z6: =IF(Y6="Sit.Normal",1,IF(Y6="Riesgo potencia",2,IF(Y6="Con Problemas",3,IF(Y6="Alto Riesgo",4,IF(Y6="Irrecuperable",5,IF(Y6="Irrec Disp Tecn",6,IF(Y6="Sin identificación",0,""))))))) -> 1 | AB6: =VLOOKUP(A6,rubros_a_considerar!$A$2:$A$13,1,FALSE) -> 141154001 | AC6: =T6+W6 -> -1108.73 | AD6: =IF(Z6<=1,Diccionario!$M$2,Diccionario!$M$3) -> 0.015 | AE6: =1-(1-AD6)^(1/365) -> 4.140637e-05 | AF6: =+IFERROR(G6-$AR$1,0) -> 0 | AG6: =+IF(AF6<=0,10*365,AF6) -> 3650 | AH6: =+IF(Z6<=1,MIN(AG6,365),AG6) -> 365 | AI6: =+(1-(AG6+1)*(1-AE6)^AG6+AG6*(1-AE6)^(AG6+1))/((1-(1-AE6)^AG6)*AE6)-0.5 -> 1779.0468 | AJ6: =+IF(Z6<3,AD6,1) -> 0.015 | AK6: =IF(Z6<=3,Diccionario!$O$2,IF(Z6=4,Diccionario!$O$5,Diccionario!$O$6)) -> 0.66499986 | AL6: =+IF(Z6<=1,1,IF(Z6=2,2,3)) -> 1 | AM6: =+IF(AC6<0,-AC6,0) -> 1108.73 | AN6: =MIN(AJ6*AK6*AM6*(1+'[2]Pesos escenarios'!$F$8/2),AM6) -> 14.740437 | AO6: =IFERROR(VLOOKUP(A6,Diccionario!$C$2:$E$65,3,FALSE),"no") -> IVA Debito Fiscal no Cobrados
A7: 141154001 | B7: 80 | C7: 57649 | D7: 42906 | E7: 0 | F7: 46142 | G7: 1753-01-01 | H7: 46142 | I7: 0 | J7: 0 | K7: 0 | L7: 0 | M7: 0 | N7: S | O7: Sit.Normal | P7: 999 | Q7: F | R7: 46142 | S7: 0 | T7: -2625.33 | U7: -1.9 | V7: -2625.33 | W7: 0 | X7: 26.25 | Y7: =TRIM(O7) -> Sit.Normal | Z7: =IF(Y7="Sit.Normal",1,IF(Y7="Riesgo potencia",2,IF(Y7="Con Problemas",3,IF(Y7="Alto Riesgo",4,IF(Y7="Irrecuperable",5,IF(Y7="Irrec Disp Tecn",6,IF(Y7="Sin identificación",0,""))))))) -> 1 | AB7: =VLOOKUP(A7,rubros_a_considerar!$A$2:$A$13,1,FALSE) -> 141154001 | AC7: =T7+W7 -> -2625.33 | AD7: =IF(Z7<=1,Diccionario!$M$2,Diccionario!$M$3) -> 0.015 | AE7: =1-(1-AD7)^(1/365) -> 4.140637e-05 | AF7: =+IFERROR(G7-$AR$1,0) -> 0 | AG7: =+IF(AF7<=0,10*365,AF7) -> 3650 | AH7: =+IF(Z7<=1,MIN(AG7,365),AG7) -> 365 | AI7: =+(1-(AG7+1)*(1-AE7)^AG7+AG7*(1-AE7)^(AG7+1))/((1-(1-AE7)^AG7)*AE7)-0.5 -> 1779.0468 | AJ7: =+IF(Z7<3,AD7,1) -> 0.015 | AK7: =IF(Z7<=3,Diccionario!$O$2,IF(Z7=4,Diccionario!$O$5,Diccionario!$O$6)) -> 0.66499986 | AL7: =+IF(Z7<=1,1,IF(Z7=2,2,3)) -> 1 | AM7: =+IF(AC7<0,-AC7,0) -> 2625.33 | AN7: =MIN(AJ7*AK7*AM7*(1+'[2]Pesos escenarios'!$F$8/2),AM7) -> 34.903457 | AO7: =IFERROR(VLOOKUP(A7,Diccionario!$C$2:$E$65,3,FALSE),"no") -> IVA Debito Fiscal no Cobrados
A8: 141154001 | B8: 80 | C8: 56956 | D8: 42856 | E8: 0 | F8: 46142 | G8: 1753-01-01 | H8: 46142 | I8: 0 | J8: 0 | K8: 0 | L8: 0 | M8: 0 | N8: S | O8: Sit.Normal | P8: 999 | Q8: F | R8: 46142 | S8: 0 | T8: -2691.65 | U8: -1.95 | V8: -2691.65 | W8: 0 | X8: 26.92 | Y8: =TRIM(O8) -> Sit.Normal | Z8: =IF(Y8="Sit.Normal",1,IF(Y8="Riesgo potencia",2,IF(Y8="Con Problemas",3,IF(Y8="Alto Riesgo",4,IF(Y8="Irrecuperable",5,IF(Y8="Irrec Disp Tecn",6,IF(Y8="Sin identificación",0,""))))))) -> 1 | AB8: =VLOOKUP(A8,rubros_a_considerar!$A$2:$A$13,1,FALSE) -> 141154001 | AC8: =T8+W8 -> -2691.65 | AD8: =IF(Z8<=1,Diccionario!$M$2,Diccionario!$M$3) -> 0.015 | AE8: =1-(1-AD8)^(1/365) -> 4.140637e-05 | AF8: =+IFERROR(G8-$AR$1,0) -> 0 | AG8: =+IF(AF8<=0,10*365,AF8) -> 3650 | AH8: =+IF(Z8<=1,MIN(AG8,365),AG8) -> 365 | AI8: =+(1-(AG8+1)*(1-AE8)^AG8+AG8*(1-AE8)^(AG8+1))/((1-(1-AE8)^AG8)*AE8)-0.5 -> 1779.0468 | AJ8: =+IF(Z8<3,AD8,1) -> 0.015 | AK8: =IF(Z8<=3,Diccionario!$O$2,IF(Z8=4,Diccionario!$O$5,Diccionario!$O$6)) -> 0.66499986 | AL8: =+IF(Z8<=1,1,IF(Z8=2,2,3)) -> 1 | AM8: =+IF(AC8<0,-AC8,0) -> 2691.65 | AN8: =MIN(AJ8*AK8*AM8*(1+'[2]Pesos escenarios'!$F$8/2),AM8) -> 35.785174 | AO8: =IFERROR(VLOOKUP(A8,Diccionario!$C$2:$E$65,3,FALSE),"no") -> IVA Debito Fiscal no Cobrados
A9: 141154001 | B9: 80 | C9: 57332 | D9: 42861 | E9: 0 | F9: 46142 | G9: 1753-01-01 | H9: 46142 | I9: 0 | J9: 0 | K9: 0 | L9: 0 | M9: 0 | N9: S | O9: Sit.Normal | P9: 999 | Q9: F | R9: 46142 | S9: 0 | T9: -3217.07 | U9: -2.33 | V9: -3217.07 | W9: 0 | X9: 32.17 | Y9: =TRIM(O9) -> Sit.Normal | Z9: =IF(Y9="Sit.Normal",1,IF(Y9="Riesgo potencia",2,IF(Y9="Con Problemas",3,IF(Y9="Alto Riesgo",4,IF(Y9="Irrecuperable",5,IF(Y9="Irrec Disp Tecn",6,IF(Y9="Sin identificación",0,""))))))) -> 1 | AB9: =VLOOKUP(A9,rubros_a_considerar!$A$2:$A$13,1,FALSE) -> 141154001 | AC9: =T9+W9 -> -3217.07 | AD9: =IF(Z9<=1,Diccionario!$M$2,Diccionario!$M$3) -> 0.015 | AE9: =1-(1-AD9)^(1/365) -> 4.140637e-05 | AF9: =+IFERROR(G9-$AR$1,0) -> 0 | AG9: =+IF(AF9<=0,10*365,AF9) -> 3650 | AH9: =+IF(Z9<=1,MIN(AG9,365),AG9) -> 365 | AI9: =+(1-(AG9+1)*(1-AE9)^AG9+AG9*(1-AE9)^(AG9+1))/((1-(1-AE9)^AG9)*AE9)-0.5 -> 1779.0468 | AJ9: =+IF(Z9<3,AD9,1) -> 0.015 | AK9: =IF(Z9<=3,Diccionario!$O$2,IF(Z9=4,Diccionario!$O$5,Diccionario!$O$6)) -> 0.66499986 | AL9: =+IF(Z9<=1,1,IF(Z9=2,2,3)) -> 1 | AM9: =+IF(AC9<0,-AC9,0) -> 3217.07 | AN9: =MIN(AJ9*AK9*AM9*(1+'[2]Pesos escenarios'!$F$8/2),AM9) -> 42.770572 | AO9: =IFERROR(VLOOKUP(A9,Diccionario!$C$2:$E$65,3,FALSE),"no") -> IVA Debito Fiscal no Cobrados
A10: 141154001 | B10: 80 | C10: 55476 | D10: 42932 | E10: 0 | F10: 46142 | G10: 1753-01-01 | H10: 46142 | I10: 0 | J10: 0 | K10: 0 | L10: 0 | M10: 0 | N10: S | O10: Sit.Normal | P10: 999 | Q10: F | R10: 46142 | S10: 0 | T10: -3428.21 | U10: -2.48 | V10: -3428.21 | W10: 0 | X10: 34.28 | Y10: =TRIM(O10) -> Sit.Normal | Z10: =IF(Y10="Sit.Normal",1,IF(Y10="Riesgo potencia",2,IF(Y10="Con Problemas",3,IF(Y10="Alto Riesgo",4,IF(Y10="Irrecuperable",5,IF(Y10="Irrec Disp Tecn",6,IF(Y10="Sin identificación",0,""))))))) -> 1 | AB10: =VLOOKUP(A10,rubros_a_considerar!$A$2:$A$13,1,FALSE) -> 141154001 | AC10: =T10+W10 -> -3428.21 | AD10: =IF(Z10<=1,Diccionario!$M$2,Diccionario!$M$3) -> 0.015 | AE10: =1-(1-AD10)^(1/365) -> 4.140637e-05 | AF10: =+IFERROR(G10-$AR$1,0) -> 0 | AG10: =+IF(AF10<=0,10*365,AF10) -> 3650 | AH10: =+IF(Z10<=1,MIN(AG10,365),AG10) -> 365 | AI10: =+(1-(AG10+1)*(1-AE10)^AG10+AG10*(1-AE10)^(AG10+1))/((1-(1-AE10)^AG10)*AE10)-0.5 -> 1779.0468 | AJ10: =+IF(Z10<3,AD10,1) -> 0.015 | AK10: =IF(Z10<=3,Diccionario!$O$2,IF(Z10=4,Diccionario!$O$5,Diccionario!$O$6)) -> 0.66499986 | AL10: =+IF(Z10<=1,1,IF(Z10=2,2,3)) -> 1 | AM10: =+IF(AC10<0,-AC10,0) -> 3428.21 | AN10: =MIN(AJ10*AK10*AM10*(1+'[2]Pesos escenarios'!$F$8/2),AM10) -> 45.577654 | AO10: =IFERROR(VLOOKUP(A10,Diccionario!$C$2:$E$65,3,FALSE),"no") -> IVA Debito Fiscal no Cobrados
A11: 141154001 | B11: 80 | C11: 83381 | D11: 42930 | E11: 0 | F11: 46142 | G11: 1753-01-01 | H11: 46142 | I11: 0 | J11: 0 | K11: 0 | L11: 0 | M11: 0 | N11: S | O11: Sit.Normal | P11: 999 | Q11: F | R11: 46142 | S11: 0 | T11: -3656.76 | U11: -2.65 | V11: -3656.76 | W11: 0 | X11: 36.57 | Y11: =TRIM(O11) -> Sit.Normal | Z11: =IF(Y11="Sit.Normal",1,IF(Y11="Riesgo potencia",2,IF(Y11="Con Problemas",3,IF(Y11="Alto Riesgo",4,IF(Y11="Irrecuperable",5,IF(Y11="Irrec Disp Tecn",6,IF(Y11="Sin identificación",0,""))))))) -> 1 | AB11: =VLOOKUP(A11,rubros_a_considerar!$A$2:$A$13,1,FALSE) -> 141154001 | AC11: =T11+W11 -> -3656.76 | AD11: =IF(Z11<=1,Diccionario!$M$2,Diccionario!$M$3) -> 0.015 | AE11: =1-(1-AD11)^(1/365) -> 4.140637e-05 | AF11: =+IFERROR(G11-$AR$1,0) -> 0 | AG11: =+IF(AF11<=0,10*365,AF11) -> 3650 | AH11: =+IF(Z11<=1,MIN(AG11,365),AG11) -> 365 | AI11: =+(1-(AG11+1)*(1-AE11)^AG11+AG11*(1-AE11)^(AG11+1))/((1-(1-AE11)^AG11)*AE11)-0.5 -> 1779.0468 | AJ11: =+IF(Z11<3,AD11,1) -> 0.015 | AK11: =IF(Z11<=3,Diccionario!$O$2,IF(Z11=4,Diccionario!$O$5,Diccionario!$O$6)) -> 0.66499986 | AL11: =+IF(Z11<=1,1,IF(Z11=2,2,3)) -> 1 | AM11: =+IF(AC11<0,-AC11,0) -> 3656.76 | AN11: =MIN(AJ11*AK11*AM11*(1+'[2]Pesos escenarios'!$F$8/2),AM11) -> 48.616199 | AO11: =IFERROR(VLOOKUP(A11,Diccionario!$C$2:$E$65,3,FALSE),"no") -> IVA Debito Fiscal no Cobrados
A12: 141154001 | B12: 80 | C12: 86245 | D12: 42921 | E12: 0 | F12: 46142 | G12: 1753-01-01 | H12: 46142 | I12: 0 | J12: 0 | K12: 0 | L12: 0 | M12: 0 | N12: S | O12: Sit.Normal | P12: 999 | Q12: F | R12: 46142 | S12: 0 | T12: -4976.63 | U12: -3.6 | V12: -4976.63 | W12: 0 | X12: 49.77 | Y12: =TRIM(O12) -> Sit.Normal | Z12: =IF(Y12="Sit.Normal",1,IF(Y12="Riesgo potencia",2,IF(Y12="Con Problemas",3,IF(Y12="Alto Riesgo",4,IF(Y12="Irrecuperable",5,IF(Y12="Irrec Disp Tecn",6,IF(Y12="Sin identificación",0,""))))))) -> 1 | AB12: =VLOOKUP(A12,rubros_a_considerar!$A$2:$A$13,1,FALSE) -> 141154001 | AC12: =T12+W12 -> -4976.63 | AD12: =IF(Z12<=1,Diccionario!$M$2,Diccionario!$M$3) -> 0.015 | AE12: =1-(1-AD12)^(1/365) -> 4.140637e-05 | AF12: =+IFERROR(G12-$AR$1,0) -> 0 | AG12: =+IF(AF12<=0,10*365,AF12) -> 3650 | AH12: =+IF(Z12<=1,MIN(AG12,365),AG12) -> 365 | AI12: =+(1-(AG12+1)*(1-AE12)^AG12+AG12*(1-AE12)^(AG12+1))/((1-(1-AE12)^AG12)*AE12)-0.5 -> 1779.0468 | AJ12: =+IF(Z12<3,AD12,1) -> 0.015 | AK12: =IF(Z12<=3,Diccionario!$O$2,IF(Z12=4,Diccionario!$O$5,Diccionario!$O$6)) -> 0.66499986 | AL12: =+IF(Z12<=1,1,IF(Z12=2,2,3)) -> 1 | AM12: =+IF(AC12<0,-AC12,0) -> 4976.63 | AN12: =MIN(AJ12*AK12*AM12*(1+'[2]Pesos escenarios'!$F$8/2),AM12) -> 66.163718 | AO12: =IFERROR(VLOOKUP(A12,Diccionario!$C$2:$E$65,3,FALSE),"no") -> IVA Debito Fiscal no Cobrados
A13: 141154001 | B13: 80 | C13: 86807 | D13: 42880 | E13: 0 | F13: 46142 | G13: 1753-01-01 | H13: 46142 | I13: 0 | J13: 0 | K13: 0 | L13: 0 | M13: 0 | N13: S | O13: Sit.Normal | P13: 999 | Q13: F | R13: 46142 | S13: 0 | T13: -6306.34 | U13: -4.57 | V13: -6306.34 | W13: 0 | X13: 63.06 | Y13: =TRIM(O13) -> Sit.Normal | Z13: =IF(Y13="Sit.Normal",1,IF(Y13="Riesgo potencia",2,IF(Y13="Con Problemas",3,IF(Y13="Alto Riesgo",4,IF(Y13="Irrecuperable",5,IF(Y13="Irrec Disp Tecn",6,IF(Y13="Sin identificación",0,""))))))) -> 1 | AB13: =VLOOKUP(A13,rubros_a_considerar!$A$2:$A$13,1,FALSE) -> 141154001 | AC13: =T13+W13 -> -6306.34 | AD13: =IF(Z13<=1,Diccionario!$M$2,Diccionario!$M$3) -> 0.015 | AE13: =1-(1-AD13)^(1/365) -> 4.140637e-05 | AF13: =+IFERROR(G13-$AR$1,0) -> 0 | AG13: =+IF(AF13<=0,10*365,AF13) -> 3650 | AH13: =+IF(Z13<=1,MIN(AG13,365),AG13) -> 365 | AI13: =+(1-(AG13+1)*(1-AE13)^AG13+AG13*(1-AE13)^(AG13+1))/((1-(1-AE13)^AG13)*AE13)-0.5 -> 1779.0468 | AJ13: =+IF(Z13<3,AD13,1) -> 0.015 | AK13: =IF(Z13<=3,Diccionario!$O$2,IF(Z13=4,Diccionario!$O$5,Diccionario!$O$6)) -> 0.66499986 | AL13: =+IF(Z13<=1,1,IF(Z13=2,2,3)) -> 1 | AM13: =+IF(AC13<0,-AC13,0) -> 6306.34 | AN13: =MIN(AJ13*AK13*AM13*(1+'[2]Pesos escenarios'!$F$8/2),AM13) -> 83.842058 | AO13: =IFERROR(VLOOKUP(A13,Diccionario!$C$2:$E$65,3,FALSE),"no") -> IVA Debito Fiscal no Cobrados
A14: 141154001 | B14: 80 | C14: 84457 | D14: 42922 | E14: 0 | F14: 46142 | G14: 1753-01-01 | H14: 46142 | I14: 0 | J14: 0 | K14: 0 | L14: 0 | M14: 0 | N14: S | O14: Sit.Normal | P14: 999 | Q14: F | R14: 46142 | S14: 0 | T14: -8847.35 | U14: -6.41 | V14: -8847.35 | W14: 0 | X14: 88.47 | Y14: =TRIM(O14) -> Sit.Normal | Z14: =IF(Y14="Sit.Normal",1,IF(Y14="Riesgo potencia",2,IF(Y14="Con Problemas",3,IF(Y14="Alto Riesgo",4,IF(Y14="Irrecuperable",5,IF(Y14="Irrec Disp Tecn",6,IF(Y14="Sin identificación",0,""))))))) -> 1 | AB14: =VLOOKUP(A14,rubros_a_considerar!$A$2:$A$13,1,FALSE) -> 141154001 | AC14: =T14+W14 -> -8847.35 | AD14: =IF(Z14<=1,Diccionario!$M$2,Diccionario!$M$3) -> 0.015 | AE14: =1-(1-AD14)^(1/365) -> 4.140637e-05 | AF14: =+IFERROR(G14-$AR$1,0) -> 0 | AG14: =+IF(AF14<=0,10*365,AF14) -> 3650 | AH14: =+IF(Z14<=1,MIN(AG14,365),AG14) -> 365 | AI14: =+(1-(AG14+1)*(1-AE14)^AG14+AG14*(1-AE14)^(AG14+1))/((1-(1-AE14)^AG14)*AE14)-0.5 -> 1779.0468 | AJ14: =+IF(Z14<3,AD14,1) -> 0.015 | AK14: =IF(Z14<=3,Diccionario!$O$2,IF(Z14=4,Diccionario!$O$5,Diccionario!$O$6)) -> 0.66499986 | AL14: =+IF(Z14<=1,1,IF(Z14=2,2,3)) -> 1 | AM14: =+IF(AC14<0,-AC14,0) -> 8847.35 | AN14: =MIN(AJ14*AK14*AM14*(1+'[2]Pesos escenarios'!$F$8/2),AM14) -> 117.62449 | AO14: =IFERROR(VLOOKUP(A14,Diccionario!$C$2:$E$65,3,FALSE),"no") -> IVA Debito Fiscal no Cobrados
A15: 141154001 | B15: 80 | C15: 55257 | D15: 42940 | E15: 0 | F15: 46142 | G15: 1753-01-01 | H15: 46142 | I15: 0 | J15: 0 | K15: 0 | L15: 0 | M15: 0 | N15: S | O15: Sit.Normal | P15: 999 | Q15: F | R15: 46142 | S15: 0 | T15: -9141.9 | U15: -6.62 | V15: -9141.9 | W15: 0 | X15: 91.42 | Y15: =TRIM(O15) -> Sit.Normal | Z15: =IF(Y15="Sit.Normal",1,IF(Y15="Riesgo potencia",2,IF(Y15="Con Problemas",3,IF(Y15="Alto Riesgo",4,IF(Y15="Irrecuperable",5,IF(Y15="Irrec Disp Tecn",6,IF(Y15="Sin identificación",0,""))))))) -> 1 | AB15: =VLOOKUP(A15,rubros_a_considerar!$A$2:$A$13,1,FALSE) -> 141154001 | AC15: =T15+W15 -> -9141.9 | AD15: =IF(Z15<=1,Diccionario!$M$2,Diccionario!$M$3) -> 0.015 | AE15: =1-(1-AD15)^(1/365) -> 4.140637e-05 | AF15: =+IFERROR(G15-$AR$1,0) -> 0 | AG15: =+IF(AF15<=0,10*365,AF15) -> 3650 | AH15: =+IF(Z15<=1,MIN(AG15,365),AG15) -> 365 | AI15: =+(1-(AG15+1)*(1-AE15)^AG15+AG15*(1-AE15)^(AG15+1))/((1-(1-AE15)^AG15)*AE15)-0.5 -> 1779.0468 | AJ15: =+IF(Z15<3,AD15,1) -> 0.015 | AK15: =IF(Z15<=3,Diccionario!$O$2,IF(Z15=4,Diccionario!$O$5,Diccionario!$O$6)) -> 0.66499986 | AL15: =+IF(Z15<=1,1,IF(Z15=2,2,3)) -> 1 | AM15: =+IF(AC15<0,-AC15,0) -> 9141.9 | AN15: =MIN(AJ15*AK15*AM15*(1+'[2]Pesos escenarios'!$F$8/2),AM15) -> 121.5405 | AO15: =IFERROR(VLOOKUP(A15,Diccionario!$C$2:$E$65,3,FALSE),"no") -> IVA Debito Fiscal no Cobrados
A16: 141154001 | B16: 80 | C16: 86774 | D16: 42931 | E16: 0 | F16: 46142 | G16: 1753-01-01 | H16: 46142 | I16: 0 | J16: 0 | K16: 0 | L16: 0 | M16: 0 | N16: S | O16: Sit.Normal | P16: 999 | Q16: F | R16: 46142 | S16: 0 | T16: -9141.9 | U16: -6.62 | V16: -9141.9 | W16: 0 | X16: 91.42 | Y16: =TRIM(O16) -> Sit.Normal | Z16: =IF(Y16="Sit.Normal",1,IF(Y16="Riesgo potencia",2,IF(Y16="Con Problemas",3,IF(Y16="Alto Riesgo",4,IF(Y16="Irrecuperable",5,IF(Y16="Irrec Disp Tecn",6,IF(Y16="Sin identificación",0,""))))))) -> 1 | AB16: =VLOOKUP(A16,rubros_a_considerar!$A$2:$A$13,1,FALSE) -> 141154001 | AC16: =T16+W16 -> -9141.9 | AD16: =IF(Z16<=1,Diccionario!$M$2,Diccionario!$M$3) -> 0.015 | AE16: =1-(1-AD16)^(1/365) -> 4.140637e-05 | AF16: =+IFERROR(G16-$AR$1,0) -> 0 | AG16: =+IF(AF16<=0,10*365,AF16) -> 3650 | AH16: =+IF(Z16<=1,MIN(AG16,365),AG16) -> 365 | AI16: =+(1-(AG16+1)*(1-AE16)^AG16+AG16*(1-AE16)^(AG16+1))/((1-(1-AE16)^AG16)*AE16)-0.5 -> 1779.0468 | AJ16: =+IF(Z16<3,AD16,1) -> 0.015 | AK16: =IF(Z16<=3,Diccionario!$O$2,IF(Z16=4,Diccionario!$O$5,Diccionario!$O$6)) -> 0.66499986 | AL16: =+IF(Z16<=1,1,IF(Z16=2,2,3)) -> 1 | AM16: =+IF(AC16<0,-AC16,0) -> 9141.9 | AN16: =MIN(AJ16*AK16*AM16*(1+'[2]Pesos escenarios'!$F$8/2),AM16) -> 121.5405 | AO16: =IFERROR(VLOOKUP(A16,Diccionario!$C$2:$E$65,3,FALSE),"no") -> IVA Debito Fiscal no Cobrados
A17: 141154001 | B17: 80 | C17: 57497 | D17: 42937 | E17: 0 | F17: 46142 | G17: 1753-01-01 | H17: 46142 | I17: 0 | J17: 0 | K17: 0 | L17: 0 | M17: 0 | N17: S | O17: Sit.Normal | P17: 999 | Q17: F | R17: 46142 | S17: 0 | T17: -9314.39 | U17: -6.74 | V17: -9314.39 | W17: 0 | X17: 93.14 | Y17: =TRIM(O17) -> Sit.Normal | Z17: =IF(Y17="Sit.Normal",1,IF(Y17="Riesgo potencia",2,IF(Y17="Con Problemas",3,IF(Y17="Alto Riesgo",4,IF(Y17="Irrecuperable",5,IF(Y17="Irrec Disp Tecn",6,IF(Y17="Sin identificación",0,""))))))) -> 1 | AB17: =VLOOKUP(A17,rubros_a_considerar!$A$2:$A$13,1,FALSE) -> 141154001 | AC17: =T17+W17 -> -9314.39 | AD17: =IF(Z17<=1,Diccionario!$M$2,Diccionario!$M$3) -> 0.015 | AE17: =1-(1-AD17)^(1/365) -> 4.140637e-05 | AF17: =+IFERROR(G17-$AR$1,0) -> 0 | AG17: =+IF(AF17<=0,10*365,AF17) -> 3650 | AH17: =+IF(Z17<=1,MIN(AG17,365),AG17) -> 365 | AI17: =+(1-(AG17+1)*(1-AE17)^AG17+AG17*(1-AE17)^(AG17+1))/((1-(1-AE17)^AG17)*AE17)-0.5 -> 1779.0468 | AJ17: =+IF(Z17<3,AD17,1) -> 0.015 | AK17: =IF(Z17<=3,Diccionario!$O$2,IF(Z17=4,Diccionario!$O$5,Diccionario!$O$6)) -> 0.66499986 | AL17: =+IF(Z17<=1,1,IF(Z17=2,2,3)) -> 1 | AM17: =+IF(AC17<0,-AC17,0) -> 9314.39 | AN17: =MIN(AJ17*AK17*AM17*(1+'[2]Pesos escenarios'!$F$8/2),AM17) -> 123.83373 | AO17: =IFERROR(VLOOKUP(A17,Diccionario!$C$2:$E$65,3,FALSE),"no") -> IVA Debito Fiscal no Cobrados | AS17: =AS15-AS16 -> 0
A18: 141154001 | B18: 80 | C18: 84662 | D18: 42960 | E18: 0 | F18: 46142 | G18: 1753-01-01 | H18: 46142 | I18: 0 | J18: 0 | K18: 0 | L18: 0 | M18: 0 | N18: S | O18: Sit.Normal | P18: 999 | Q18: F | R18: 46142 | S18: 0 | T18: -9450 | U18: -6.84 | V18: -9450 | W18: 0 | X18: 94.5 | Y18: =TRIM(O18) -> Sit.Normal | Z18: =IF(Y18="Sit.Normal",1,IF(Y18="Riesgo potencia",2,IF(Y18="Con Problemas",3,IF(Y18="Alto Riesgo",4,IF(Y18="Irrecuperable",5,IF(Y18="Irrec Disp Tecn",6,IF(Y18="Sin identificación",0,""))))))) -> 1 | AB18: =VLOOKUP(A18,rubros_a_considerar!$A$2:$A$13,1,FALSE) -> 141154001 | AC18: =T18+W18 -> -9450 | AD18: =IF(Z18<=1,Diccionario!$M$2,Diccionario!$M$3) -> 0.015 | AE18: =1-(1-AD18)^(1/365) -> 4.140637e-05 | AF18: =+IFERROR(G18-$AR$1,0) -> 0 | AG18: =+IF(AF18<=0,10*365,AF18) -> 3650 | AH18: =+IF(Z18<=1,MIN(AG18,365),AG18) -> 365 | AI18: =+(1-(AG18+1)*(1-AE18)^AG18+AG18*(1-AE18)^(AG18+1))/((1-(1-AE18)^AG18)*AE18)-0.5 -> 1779.0468 | AJ18: =+IF(Z18<3,AD18,1) -> 0.015 | AK18: =IF(Z18<=3,Diccionario!$O$2,IF(Z18=4,Diccionario!$O$5,Diccionario!$O$6)) -> 0.66499986 | AL18: =+IF(Z18<=1,1,IF(Z18=2,2,3)) -> 1 | AM18: =+IF(AC18<0,-AC18,0) -> 9450 | AN18: =MIN(AJ18*AK18*AM18*(1+'[2]Pesos escenarios'!$F$8/2),AM18) -> 125.63665 | AO18: =IFERROR(VLOOKUP(A18,Diccionario!$C$2:$E$65,3,FALSE),"no") -> IVA Debito Fiscal no Cobrados
A19: 141154001 | B19: 80 | C19: 85825 | D19: 42947 | E19: 0 | F19: 46142 | G19: 1753-01-01 | H19: 46142 | I19: 0 | J19: 0 | K19: 0 | L19: 0 | M19: 0 | N19: S | O19: Sit.Normal | P19: 999 | Q19: F | R19: 46142 | S19: 0 | T19: -9481.27 | U19: -6.87 | V19: -9481.27 | W19: 0 | X19: 94.81 | Y19: =TRIM(O19) -> Sit.Normal | Z19: =IF(Y19="Sit.Normal",1,IF(Y19="Riesgo potencia",2,IF(Y19="Con Problemas",3,IF(Y19="Alto Riesgo",4,IF(Y19="Irrecuperable",5,IF(Y19="Irrec Disp Tecn",6,IF(Y19="Sin identificación",0,""))))))) -> 1 | AB19: =VLOOKUP(A19,rubros_a_considerar!$A$2:$A$13,1,FALSE) -> 141154001 | AC19: =T19+W19 -> -9481.27 | AD19: =IF(Z19<=1,Diccionario!$M$2,Diccionario!$M$3) -> 0.015 | AE19: =1-(1-AD19)^(1/365) -> 4.140637e-05 | AF19: =+IFERROR(G19-$AR$1,0) -> 0 | AG19: =+IF(AF19<=0,10*365,AF19) -> 3650 | AH19: =+IF(Z19<=1,MIN(AG19,365),AG19) -> 365 | AI19: =+(1-(AG19+1)*(1-AE19)^AG19+AG19*(1-AE19)^(AG19+1))/((1-(1-AE19)^AG19)*AE19)-0.5 -> 1779.0468 | AJ19: =+IF(Z19<3,AD19,1) -> 0.015 | AK19: =IF(Z19<=3,Diccionario!$O$2,IF(Z19=4,Diccionario!$O$5,Diccionario!$O$6)) -> 0.66499986 | AL19: =+IF(Z19<=1,1,IF(Z19=2,2,3)) -> 1 | AM19: =+IF(AC19<0,-AC19,0) -> 9481.27 | AN19: =MIN(AJ19*AK19*AM19*(1+'[2]Pesos escenarios'!$F$8/2),AM19) -> 126.05238 | AO19: =IFERROR(VLOOKUP(A19,Diccionario!$C$2:$E$65,3,FALSE),"no") -> IVA Debito Fiscal no Cobrados
A20: 141154001 | B20: 80 | C20: 86883 | D20: 42962 | E20: 0 | F20: 46142 | G20: 1753-01-01 | H20: 46142 | I20: 0 | J20: 0 | K20: 0 | L20: 0 | M20: 0 | N20: S | O20: Sit.Normal | P20: 999 | Q20: F | R20: 46142 | S20: 0 | T20: -10416 | U20: -7.54 | V20: -10416 | W20: 0 | X20: 104.16 | Y20: =TRIM(O20) -> Sit.Normal | Z20: =IF(Y20="Sit.Normal",1,IF(Y20="Riesgo potencia",2,IF(Y20="Con Problemas",3,IF(Y20="Alto Riesgo",4,IF(Y20="Irrecuperable",5,IF(Y20="Irrec Disp Tecn",6,IF(Y20="Sin identificación",0,""))))))) -> 1 | AB20: =VLOOKUP(A20,rubros_a_considerar!$A$2:$A$13,1,FALSE) -> 141154001 | AC20: =T20+W20 -> -10416 | AD20: =IF(Z20<=1,Diccionario!$M$2,Diccionario!$M$3) -> 0.015 | AE20: =1-(1-AD20)^(1/365) -> 4.140637e-05 | AF20: =+IFERROR(G20-$AR$1,0) -> 0 | AG20: =+IF(AF20<=0,10*365,AF20) -> 3650 | AH20: =+IF(Z20<=1,MIN(AG20,365),AG20) -> 365 | AI20: =+(1-(AG20+1)*(1-AE20)^AG20+AG20*(1-AE20)^(AG20+1))/((1-(1-AE20)^AG20)*AE20)-0.5 -> 1779.0468 | AJ20: =+IF(Z20<3,AD20,1) -> 0.015 | AK20: =IF(Z20<=3,Diccionario!$O$2,IF(Z20=4,Diccionario!$O$5,Diccionario!$O$6)) -> 0.66499986 | AL20: =+IF(Z20<=1,1,IF(Z20=2,2,3)) -> 1 | AM20: =+IF(AC20<0,-AC20,0) -> 10416 | AN20: =MIN(AJ20*AK20*AM20*(1+'[2]Pesos escenarios'!$F$8/2),AM20) -> 138.47951 | AO20: =IFERROR(VLOOKUP(A20,Diccionario!$C$2:$E$65,3,FALSE),"no") -> IVA Debito Fiscal no Cobrados
A21: 131715001 | B21: 80 | C21: 6206 | D21: 36882 | E21: 0 | F21: 46142 | G21: 46178 | H21: 45082 | I21: 1080 | J21: 2 | K21: 66 | L21: 1 | M21: 2 | N21: S | O21: Sit.Normal | P21: 466 | Q21: J | R21: 45082 | S21: 1250000 | T21: -147670.72 | U21: -106.92 | V21: -147670.72 | W21: -6675.53 | X21: 1543.46 | Y21: =TRIM(O21) -> Sit.Normal | Z21: =IF(Y21="Sit.Normal",1,IF(Y21="Riesgo potencia",2,IF(Y21="Con Problemas",3,IF(Y21="Alto Riesgo",4,IF(Y21="Irrecuperable",5,IF(Y21="Irrec Disp Tecn",6,IF(Y21="Sin identificación",0,""))))))) -> 1 | AB21: =VLOOKUP(A21,rubros_a_considerar!$A$2:$A$13,1,FALSE) -> 131715001 | AC21: =T21+W21 -> -154346.25 | AD21: =IF(Z21<=1,Diccionario!$M$2,Diccionario!$M$3) -> 0.015 | AE21: =1-(1-AD21)^(1/365) -> 4.140637e-05 | AF21: =+IFERROR(G21-$AR$1,0) -> 36 | AG21: =+IF(AF21<=0,10*365,AF21) -> 36 | AH21: =+IF(Z21<=1,MIN(AG21,365),AG21) -> 36 | AI21: =+(1-(AG21+1)*(1-AE21)^AG21+AG21*(1-AE21)^(AG21+1))/((1-(1-AE21)^AG21)*AE21)-0.5 -> 17.995532 | AJ21: =+IF(Z21<3,AD21,1) -> 0.015 | AK21: =IF(Z21<=3,Diccionario!$O$2,IF(Z21=4,Diccionario!$O$5,Diccionario!$O$6)) -> 0.66499986 | AL21: =+IF(Z21<=1,1,IF(Z21=2,2,3)) -> 1 | AM21: =+IF(AC21<0,-AC21,0) -> 154346.25 | AN21: =MIN(AJ21*AK21*AM21*(1+'[2]Pesos escenarios'!$F$8/2),AM21) -> 2052.0155 | AO21: =IFERROR(VLOOKUP(A21,Diccionario!$C$2:$E$65,3,FALSE),"no") -> Prestamos a Sola Firma
A22: 131715001 | B22: 80 | C22: 13957 | D22: 36870 | E22: 0 | F22: 46142 | G22: 46307 | H22: 44845 | I22: 1441 | J22: 2 | K22: 66 | L22: 1 | M22: 2 | N22: S | O22: Sit.Normal | P22: 202 | Q22: J | R22: 44845 | S22: 2000000 | T22: -592060.45 | U22: -428.69 | V22: -592060.45 | W22: -19270.35 | X22: 6113.31 | Y22: =TRIM(O22) -> Sit.Normal | Z22: =IF(Y22="Sit.Normal",1,IF(Y22="Riesgo potencia",2,IF(Y22="Con Problemas",3,IF(Y22="Alto Riesgo",4,IF(Y22="Irrecuperable",5,IF(Y22="Irrec Disp Tecn",6,IF(Y22="Sin identificación",0,""))))))) -> 1 | AB22: =VLOOKUP(A22,rubros_a_considerar!$A$2:$A$13,1,FALSE) -> 131715001 | AC22: =T22+W22 -> -611330.8 | AD22: =IF(Z22<=1,Diccionario!$M$2,Diccionario!$M$3) -> 0.015 | AE22: =1-(1-AD22)^(1/365) -> 4.140637e-05 | AF22: =+IFERROR(G22-$AR$1,0) -> 165 | AG22: =+IF(AF22<=0,10*365,AF22) -> 165 | AH22: =+IF(Z22<=1,MIN(AG22,365),AG22) -> 165 | AI22: =+(1-(AG22+1)*(1-AE22)^AG22+AG22*(1-AE22)^(AG22+1))/((1-(1-AE22)^AG22)*AE22)-0.5 -> 82.406061 | AJ22: =+IF(Z22<3,AD22,1) -> 0.015 | AK22: =IF(Z22<=3,Diccionario!$O$2,IF(Z22=4,Diccionario!$O$5,Diccionario!$O$6)) -> 0.66499986 | AL22: =+IF(Z22<=1,1,IF(Z22=2,2,3)) -> 1 | AM22: =+IF(AC22<0,-AC22,0) -> 611330.8 | AN22: =MIN(AJ22*AK22*AM22*(1+'[2]Pesos escenarios'!$F$8/2),AM22) -> 8127.572 | AO22: =IFERROR(VLOOKUP(A22,Diccionario!$C$2:$E$65,3,FALSE),"no") -> Prestamos a Sola Firma
A23: 131715001 | B23: 80 | C23: 13957 | D23: 36869 | E23: 0 | F23: 46142 | G23: 46279 | H23: 44818 | I23: 1440 | J23: 2 | K23: 66 | L23: 1 | M23: 2 | N23: S | O23: Sit.Normal | P23: 202 | Q23: J | R23: 44818 | S23: 3000000 | T23: -756500.84 | U23: -547.75 | V23: -756500.84 | W23: -23254.63 | X23: 7797.55 | Y23: =TRIM(O23) -> Sit.Normal | Z23: =IF(Y23="Sit.Normal",1,IF(Y23="Riesgo potencia",2,IF(Y23="Con Problemas",3,IF(Y23="Alto Riesgo",4,IF(Y23="Irrecuperable",5,IF(Y23="Irrec Disp Tecn",6,IF(Y23="Sin identificación",0,""))))))) -> 1 | AB23: =VLOOKUP(A23,rubros_a_considerar!$A$2:$A$13,1,FALSE) -> 131715001 | AC23: =T23+W23 -> -779755.47 | AD23: =IF(Z23<=1,Diccionario!$M$2,Diccionario!$M$3) -> 0.015 | AE23: =1-(1-AD23)^(1/365) -> 4.140637e-05 | AF23: =+IFERROR(G23-$AR$1,0) -> 137 | AG23: =+IF(AF23<=0,10*365,AF23) -> 137 | AH23: =+IF(Z23<=1,MIN(AG23,365),AG23) -> 137 | AI23: =+(1-(AG23+1)*(1-AE23)^AG23+AG23*(1-AE23)^(AG23+1))/((1-(1-AE23)^AG23)*AE23)-0.5 -> 68.435239 | AJ23: =+IF(Z23<3,AD23,1) -> 0.015 | AK23: =IF(Z23<=3,Diccionario!$O$2,IF(Z23=4,Diccionario!$O$5,Diccionario!$O$6)) -> 0.66499986 | AL23: =+IF(Z23<=1,1,IF(Z23=2,2,3)) -> 1 | AM23: =+IF(AC23<0,-AC23,0) -> 779755.47 | AN23: =MIN(AJ23*AK23*AM23*(1+'[2]Pesos escenarios'!$F$8/2),AM23) -> 10366.758 | AO23: =IFERROR(VLOOKUP(A23,Diccionario!$C$2:$E$65,3,FALSE),"no") -> Prestamos a Sola Firma
A24: 131731003 | B24: 80 | C24: 82510 | D24: 42796 | E24: 0 | F24: 46142 | G24: 46147 | H24: 45782 | I24: 360 | J24: 2 | K24: 52 | L24: 1 | M24: 2 | N24: S | O24: Sit.Normal | P24: 999 | Q24: F | R24: 45782 | S24: 200000 | T24: -20801.48 | U24: -15.06 | V24: -20801.48 | W24: -740.87 | X24: 215.42 | Y24: =TRIM(O24) -> Sit.Normal | Z24: =IF(Y24="Sit.Normal",1,IF(Y24="Riesgo potencia",2,IF(Y24="Con Problemas",3,IF(Y24="Alto Riesgo",4,IF(Y24="Irrecuperable",5,IF(Y24="Irrec Disp Tecn",6,IF(Y24="Sin identificación",0,""))))))) -> 1 | AB24: =VLOOKUP(A24,rubros_a_considerar!$A$2:$A$13,1,FALSE) -> 131731003 | AC24: =T24+W24 -> -21542.35 | AD24: =IF(Z24<=1,Diccionario!$M$2,Diccionario!$M$3) -> 0.015 | AE24: =1-(1-AD24)^(1/365) -> 4.140637e-05 | AF24: =+IFERROR(G24-$AR$1,0) -> 5 | AG24: =+IF(AF24<=0,10*365,AF24) -> 5 | AH24: =+IF(Z24<=1,MIN(AG24,365),AG24) -> 5 | AI24: =+(1-(AG24+1)*(1-AE24)^AG24+AG24*(1-AE24)^(AG24+1))/((1-(1-AE24)^AG24)*AE24)-0.5 -> 2.4999171 | AJ24: =+IF(Z24<3,AD24,1) -> 0.015 | AK24: =IF(Z24<=3,Diccionario!$O$2,IF(Z24=4,Diccionario!$O$5,Diccionario!$O$6)) -> 0.66499986 | AL24: =+IF(Z24<=1,1,IF(Z24=2,2,3)) -> 1 | AM24: =+IF(AC24<0,-AC24,0) -> 21542.35 | AN24: =MIN(AJ24*AK24*AM24*(1+'[2]Pesos escenarios'!$F$8/2),AM24) -> 286.40304 | AO24: =IFERROR(VLOOKUP(A24,Diccionario!$C$2:$E$65,3,FALSE),"no") -> Prestamos Personales
